<?xml version="1.0" encoding="utf-8"?>

<robot name="racebot" xmlns:xacro="http://www.ros.org/wiki/xacro">

  <!-- Tire rotational resistance: rotation_fiction -->
  <xacro:property name="rotation_fiction" value="1"/>
  <!-- Tire grip: mu-->
  <xacro:property name="mu" value="9999999999.0"/>

  <xacro:include filename="$(find sipder_robot)/xacro/macros.xacro" />

<!-- STL model -->
  <link name="base_footprint"/>
  <joint name="base_link2base_footprint" type="fixed">
    <parent link="base_footprint"/>
    <child link="base_link"/>
    <origin rpy="0 0 0" xyz="0.0 0.0 0.04"/>
  </joint>

  <link name="base_link">
    <visual>
      <origin rpy="0 0 0" xyz="0 0 0"/>
      <geometry>
        <mesh filename="package://sipder_robot/meshes/nanocar/base_link.obj"/>
      </geometry>
      <material name="">
        <color rgba="1 1 1 1"/>
      </material>
    </visual>
    <collision>
      <origin rpy="0 0 0" xyz="0.075 0 0.0475"/>
      <geometry>
        <box size="0.21 0.1 0.095"/>
      </geometry>
      <!-- <origin rpy="0 0 0" xyz="0 0 0"/>
      <geometry>
        <mesh filename="package://sipder_robot/meshes/nanocar/base_link.obj"/>
      </geometry> -->
    </collision>
  </link>

    <!-- base_inertia -->
    <link name="base_inertia">
      <inertial>
        <origin rpy="0 0 0" xyz="0.072991 0.00046853 0.039966"/>
        <mass value="0.45437"/>
        <inertia ixx="0.00029844" ixy="-4.3951E-06" ixz="-2.191E-06" iyy="0.00043198" iyz="3.005E-07" izz="0.00068218"/>
      </inertial>
    </link>

    <!-- chassis_inertia_joint -->
    <joint name="chassis_inertia_joint" type="fixed">
      <origin xyz="0 0 0" rpy="0 0 0" />
      <parent link="base_link" />
      <child link="base_inertia" />
    </joint>

  <link name="left_front_wheel">
    <inertial>
      <origin rpy="0 0 0" xyz="-1.914E-05 -4.1633E-16 -0.0055056"/>
      <mass value="0.056134"/>
      <inertia ixx="2.4529E-05" ixy="1.012E-19" ixz="6.1905E-08" iyy="2.4528E-05" iyz="1.0409E-17" izz="4.2335E-05"/>
    </inertial>
    <visual>
      <origin rpy="0 0 0" xyz="0 0 0"/>
      <geometry>
        <mesh filename="package://sipder_robot/meshes/nanocar/front_left_wheel_link.obj"/>
      </geometry>
      <material name="">
        <color rgba="0.1098 0.1098 0.1098 1"/>
      </material>
    </visual>
    <collision>
      <origin rpy="0 0 0" xyz="0 0 0"/>
      <geometry>
        <mesh filename="package://sipder_robot/meshes/nanocar/front_left_wheel_link.obj"/>
      </geometry>
    </collision>
    <xacro:wheel_friction name="${mu}" />
  </link>
  <joint name="left_front_wheel_joint" type="continuous">
    <!-- <origin rpy="-1.5708 0 0" xyz="0.14338 0.08725 0.0179"/> -->
    <origin rpy="0 0 0" xyz="0 0 0.03725"/>
    <parent link="left_steering_hinge"/>
    <child link="left_front_wheel"/>
    <axis xyz="0 0 1"/>
  </joint>
  <xacro:wheel_transmission name="left_front_wheel" />

  <link name="left_steering_hinge">
    <!-- <visual>
      <origin rpy="0 0 0" xyz="0 0 0"/>
      <geometry>
        <sphere radius="0.0001"/>
      </geometry>
      <material name="">
        <color rgba="0.1098 0.1098 0.1098 1"/>
      </material>
    </visual> -->
    <inertial>
      <origin xyz="0 0 0" />
      <mass value="0.5" />
      <inertia ixx="1.35E-05" ixy="0" ixz="0" iyy="1.35E-05" iyz="0" izz="2.5E-05" />
    </inertial>
  </link>
  <joint name="left_steering_hinge_joint" type="revolute">
    <parent link="base_link"/>
    <child link="left_steering_hinge"/>
    <origin rpy="-1.5708 0 0" xyz="0.14338 0.05 0.0179"/>
    <limit effort="30" velocity="2.0" lower="-0.7854" upper="0.7854" />
    <axis xyz="0 -1 0"/>
  </joint>
  <xacro:steering_hinge_transmission name="left_steering_hinge" />

  <link name="right_front_wheel">
    <inertial>
      <origin rpy="0 0 0" xyz="-1.914E-05 -4.1633E-16 -0.0055056"/>
      <mass value="0.056134"/>
      <inertia ixx="2.4529E-05" ixy="1.012E-19" ixz="6.1905E-08" iyy="2.4528E-05" iyz="1.0409E-17" izz="4.2335E-05"/>
    </inertial>
    <visual>
      <origin rpy="0 0 0" xyz="0 0 0"/>
      <geometry>
        <mesh filename="package://sipder_robot/meshes/nanocar/front_right_wheel_link.obj"/>
      </geometry>
      <material name="">
        <color rgba="0.1098 0.1098 0.1098 1"/>
      </material>
    </visual>
    <collision>
      <origin rpy="0 0 0" xyz="0 0 0"/>
      <geometry>
        <mesh filename="package://sipder_robot/meshes/nanocar/front_right_wheel_link.obj"/>
      </geometry>
    </collision>
    <xacro:wheel_friction name="${mu}" />
  </link>
  <joint name="right_front_wheel_joint" type="continuous">
    <!-- <origin rpy="-1.5708 0 -3.1416" xyz="0.14338 -0.08725 0.0179"/> -->
    <origin rpy="0 0 0" xyz="0 0 0.03725"/>
    <parent link="right_steering_hinge"/>
    <child link="right_front_wheel"/>
    <axis xyz="0 0 -1"/>
  </joint>
  <xacro:wheel_transmission name="right_front_wheel" />

  <link name="right_steering_hinge">
    <!-- <visual>
      <origin rpy="0 0 0" xyz="0 0 0"/>
      <geometry>
        <sphere radius="0.0001"/>
      </geometry>
      <material name="">
        <color rgba="0.1098 0.1098 0.1098 1"/>
      </material>
    </visual> -->
    <inertial>
      <origin xyz="0 0 0" />
      <mass value="0.5" />
      <inertia ixx="1.35E-05" ixy="0" ixz="0" iyy="1.35E-05" iyz="0" izz="2.5E-05" />
    </inertial>
  </link>
  <joint name="right_steering_hinge_joint" type="revolute">
    <parent link="base_link"/>
    <child link="right_steering_hinge"/>
    <origin rpy="-1.5708 0 -3.1416" xyz="0.14338 -0.05 0.0179"/>
    <limit effort="30" velocity="2.0" lower="-0.7854" upper="0.7854" />
    <axis xyz="0 -1 0"/>
  </joint>
  <xacro:steering_hinge_transmission name="right_steering_hinge" />

  <link name="left_rear_wheel">
    <inertial>
      <origin rpy="0 0 0" xyz="-1.914E-05 -4.1633E-16 -0.0055056"/>
      <mass value="0.056134"/>
      <inertia ixx="2.4529E-05" ixy="1.012E-19" ixz="6.1905E-08" iyy="2.4528E-05" iyz="1.0409E-17" izz="4.2335E-05"/>
    </inertial>
    <visual>
      <origin rpy="0 0 0" xyz="0 0 0"/>
      <geometry>
        <mesh filename="package://sipder_robot/meshes/nanocar/back_left_wheel_link.obj"/>
      </geometry>
      <material name="">
        <color rgba="0.1098 0.1098 0.1098 1"/>
      </material>
    </visual>
    <collision>
      <origin rpy="0 0 0" xyz="0 0 0"/>
      <geometry>
        <mesh filename="package://sipder_robot/meshes/nanocar/back_left_wheel_link.obj"/>
      </geometry>
    </collision>
    <xacro:wheel_friction name="${mu}" />
  </link>
  <joint name="left_rear_wheel_joint" type="continuous">
    <origin rpy="-1.5708 0 0" xyz="-0.00015 0.08725 0.0179"/>
    <parent link="base_link"/>
    <child link="left_rear_wheel"/>
    <axis xyz="0 0 1"/>
  </joint>
  <xacro:wheel_transmission name="left_rear_wheel" />

  <link name="right_rear_wheel">
    <inertial>
      <origin rpy="0 0 0" xyz="-1.914E-05 -4.1633E-16 -0.0055056"/>
      <mass value="0.056134"/>
      <inertia ixx="2.4529E-05" ixy="1.012E-19" ixz="6.1905E-08" iyy="2.4528E-05" iyz="1.0409E-17" izz="4.2335E-05"/>
    </inertial>
    <visual>
      <origin rpy="0 0 0" xyz="0 0 0"/>
      <geometry>
        <mesh filename="package://sipder_robot/meshes/nanocar/back_right_wheel_link.obj"/>
      </geometry>
      <material name="">
        <color rgba="0.1098 0.1098 0.1098 1"/>
      </material>
    </visual>
    <collision>
      <origin rpy="0 0 0" xyz="0 0 0"/>
      <geometry>
        <mesh filename="package://sipder_robot/meshes/nanocar/back_right_wheel_link.obj"/>
      </geometry>
    </collision>
    <xacro:wheel_friction name="${mu}" />
  </link>
  <joint name="right_rear_wheel_joint" type="continuous">
    <origin rpy="-1.5708 0 3.1416" xyz="0.00015 -0.08725 0.0179"/>
    <parent link="base_link"/>
    <child link="right_rear_wheel"/>
    <axis xyz="0 0 -1"/>
  </joint>
  <xacro:wheel_transmission name="right_rear_wheel" />

  <!-- laser -->
  <link name="base_laser_link"/>
  <joint name="laser_joint" type="fixed">
    <origin rpy="0 0 3.1416" xyz="0.11449 0 0.141"/>
    <parent link="base_link"/>
    <child link="base_laser_link"/>
    <axis xyz="0 0 0"/>
  </joint>
  
  <!-- rgb camera -->
  <link name="base_camera_link"/>
  <joint name="camera_joint" type="fixed">
    <origin rpy="0 0 0" xyz="0.15917 0.019164 0.073"/>
    <parent link="base_link"/>
    <child link="base_camera_link"/>
    <axis xyz="0 0 0"/>
  </joint>

  <!-- imu -->
  <link name="imu"/>
  <joint name="imu_joint" type="fixed">
    <origin rpy="0 0 0" xyz="0.0653 -0.0275 0.07671"/>
    <parent link="base_link"/>
    <child link="imu"/>
    <axis xyz="0 0 0"/>
  </joint>

  <!-- ir camera -->
  <link name="camera_link"/>
  <joint name="ir_camera_joint" type="fixed">
    <origin rpy="0 0 0" xyz="0.15917 0.039164 0.073"/>
    <parent link="base_link"/>
    <child link="camera_link"/>
    <axis xyz="0 0 0"/>
  </joint>

  <xacro:include filename="$(find sipder_robot)/xacro/racecar.gazebo" />

</robot>

