<sdf version='1.7'>
  <world name='default'>
    <light name='sun' type='directional'>
      <cast_shadows>1</cast_shadows>
      <pose>0 0 10 0 -0 0</pose>
      <diffuse>0.8 0.8 0.8 1</diffuse>
      <specular>0.2 0.2 0.2 1</specular>
      <attenuation>
        <range>1000</range>
        <constant>0.9</constant>
        <linear>0.01</linear>
        <quadratic>0.001</quadratic>
      </attenuation>
      <direction>-0.5 0.1 -0.9</direction>
      <spot>
        <inner_angle>0</inner_angle>
        <outer_angle>0</outer_angle>
        <falloff>0</falloff>
      </spot>
    </light>
    <model name='ground_plane'>
      <static>1</static>
      <link name='link'>
        <collision name='collision'>
          <geometry>
            <plane>
              <normal>0 0 1</normal>
              <size>100 100</size>
            </plane>
          </geometry>
          <surface>
            <contact>
              <collide_bitmask>65535</collide_bitmask>
              <ode/>
            </contact>
            <friction>
              <ode>
                <mu>100</mu>
                <mu2>50</mu2>
              </ode>
              <torsional>
                <ode/>
              </torsional>
            </friction>
            <bounce/>
          </surface>
          <max_contacts>10</max_contacts>
        </collision>
        <visual name='visual'>
          <cast_shadows>0</cast_shadows>
          <geometry>
            <plane>
              <normal>0 0 1</normal>
              <size>100 100</size>
            </plane>
          </geometry>
          <material>
            <script>
              <uri>file://media/materials/scripts/gazebo.material</uri>
              <name>Gazebo/Grey</name>
            </script>
          </material>
        </visual>
        <self_collide>0</self_collide>
        <enable_wind>0</enable_wind>
        <kinematic>0</kinematic>
      </link>
    </model>
    <gravity>0 0 -9.8</gravity>
    <magnetic_field>6e-06 2.3e-05 -4.2e-05</magnetic_field>
    <atmosphere type='adiabatic'/>
    <physics type='ode'>
      <max_step_size>0.001</max_step_size>
      <real_time_factor>1</real_time_factor>
      <real_time_update_rate>1000</real_time_update_rate>
    </physics>
    <scene>
      <ambient>0.4 0.4 0.4 1</ambient>
      <background>0.7 0.7 0.7 1</background>
      <shadows>1</shadows>
    </scene>
    <wind/>
    <spherical_coordinates>
      <surface_model>EARTH_WGS84</surface_model>
      <latitude_deg>0</latitude_deg>
      <longitude_deg>0</longitude_deg>
      <elevation>0</elevation>
      <heading_deg>0</heading_deg>
    </spherical_coordinates>
    <model name='box_house'>
      <pose>-1.97643 0.059964 0 0 -0 0</pose>
      <link name='Wall_1'>
        <collision name='Wall_1_Collision'>
          <geometry>
            <box>
              <size>13 0.15 2.5</size>
            </box>
          </geometry>
          <pose>0 0 1.25 0 -0 0</pose>
          <surface>
            <contact>
              <ode/>
            </contact>
            <bounce/>
            <friction>
              <torsional>
                <ode/>
              </torsional>
              <ode/>
            </friction>
          </surface>
          <max_contacts>10</max_contacts>
        </collision>
        <visual name='Wall_1_Visual'>
          <pose>0 0 1.25 0 -0 0</pose>
          <geometry>
            <box>
              <size>13 0.15 2.5</size>
            </box>
          </geometry>
          <material>
            <script>
              <uri>file://media/materials/scripts/gazebo.material</uri>
              <name>Gazebo/CeilingTiled</name>
            </script>
            <ambient>1 1 1 1</ambient>
          </material>
          <meta>
            <layer>0</layer>
          </meta>
        </visual>
        <pose>0 3.925 0 0 -0 0</pose>
        <self_collide>0</self_collide>
        <enable_wind>0</enable_wind>
        <kinematic>0</kinematic>
      </link>
      <link name='Wall_2'>
        <collision name='Wall_2_Collision'>
          <geometry>
            <box>
              <size>8 0.15 2.5</size>
            </box>
          </geometry>
          <pose>0 0 1.25 0 -0 0</pose>
          <surface>
            <contact>
              <ode/>
            </contact>
            <bounce/>
            <friction>
              <torsional>
                <ode/>
              </torsional>
              <ode/>
            </friction>
          </surface>
          <max_contacts>10</max_contacts>
        </collision>
        <visual name='Wall_2_Visual'>
          <pose>0 0 1.25 0 -0 0</pose>
          <geometry>
            <box>
              <size>8 0.15 2.5</size>
            </box>
          </geometry>
          <material>
            <script>
              <uri>file://media/materials/scripts/gazebo.material</uri>
              <name>Gazebo/Bricks</name>
            </script>
            <ambient>1 1 1 1</ambient>
          </material>
          <meta>
            <layer>0</layer>
          </meta>
        </visual>
        <pose>6.425 -0 0 0 -0 -1.5708</pose>
        <self_collide>0</self_collide>
        <enable_wind>0</enable_wind>
        <kinematic>0</kinematic>
      </link>
      <link name='Wall_3'>
        <collision name='Wall_3_Collision'>
          <geometry>
            <box>
              <size>13 0.15 2.5</size>
            </box>
          </geometry>
          <pose>0 0 1.25 0 -0 0</pose>
          <surface>
            <contact>
              <ode/>
            </contact>
            <bounce/>
            <friction>
              <torsional>
                <ode/>
              </torsional>
              <ode/>
            </friction>
          </surface>
          <max_contacts>10</max_contacts>
        </collision>
        <visual name='Wall_3_Visual'>
          <pose>0 0 1.25 0 -0 0</pose>
          <geometry>
            <box>
              <size>13 0.15 2.5</size>
            </box>
          </geometry>
          <material>
            <script>
              <uri>file://media/materials/scripts/gazebo.material</uri>
              <name>Gazebo/CeilingTiled</name>
            </script>
            <ambient>1 1 1 1</ambient>
          </material>
          <meta>
            <layer>0</layer>
          </meta>
        </visual>
        <pose>0 -3.925 0 0 -0 3.14159</pose>
        <self_collide>0</self_collide>
        <enable_wind>0</enable_wind>
        <kinematic>0</kinematic>
      </link>
      <link name='Wall_4'>
        <collision name='Wall_4_Collision'>
          <geometry>
            <box>
              <size>8 0.15 2.5</size>
            </box>
          </geometry>
          <pose>0 0 1.25 0 -0 0</pose>
          <surface>
            <contact>
              <ode/>
            </contact>
            <bounce/>
            <friction>
              <torsional>
                <ode/>
              </torsional>
              <ode/>
            </friction>
          </surface>
          <max_contacts>10</max_contacts>
        </collision>
        <visual name='Wall_4_Visual'>
          <pose>0 0 1.25 0 -0 0</pose>
          <geometry>
            <box>
              <size>8 0.15 2.5</size>
            </box>
          </geometry>
          <material>
            <script>
              <uri>file://media/materials/scripts/gazebo.material</uri>
              <name>Gazebo/Wood</name>
            </script>
            <ambient>1 1 1 1</ambient>
          </material>
          <meta>
            <layer>0</layer>
          </meta>
        </visual>
        <pose>-6.425 -0 0 0 -0 1.5708</pose>
        <self_collide>0</self_collide>
        <enable_wind>0</enable_wind>
        <kinematic>0</kinematic>
      </link>
      <static>1</static>
    </model>
    <model name='unit_box'>
      <pose>-7.27143 3.09748 0.5 0 -0 0</pose>
      <link name='link'>
        <inertial>
          <mass>1</mass>
          <inertia>
            <ixx>0.166667</ixx>
            <ixy>0</ixy>
            <ixz>0</ixz>
            <iyy>0.166667</iyy>
            <iyz>0</iyz>
            <izz>0.166667</izz>
          </inertia>
          <pose>0 0 0 0 -0 0</pose>
        </inertial>
        <collision name='collision'>
          <geometry>
            <box>
              <size>1 1 1</size>
            </box>
          </geometry>
          <surface>
            <contact>
              <ode/>
            </contact>
            <bounce/>
            <friction>
              <torsional>
                <ode/>
              </torsional>
              <ode/>
            </friction>
          </surface>
          <max_contacts>10</max_contacts>
        </collision>
        <visual name='visual'>
          <geometry>
            <box>
              <size>1 1 1</size>
            </box>
          </geometry>
          <material>
            <script>
              <name>Gazebo/Grey</name>
              <uri>file://media/materials/scripts/gazebo.material</uri>
            </script>
          </material>
        </visual>
        <self_collide>0</self_collide>
        <enable_wind>0</enable_wind>
        <kinematic>0</kinematic>
      </link>
    </model>
    <model name='unit_cylinder'>
      <pose>-4.57746 0.509886 0.5 0 -0 0</pose>
      <link name='link'>
        <inertial>
          <mass>1</mass>
          <inertia>
            <ixx>0.145833</ixx>
            <ixy>0</ixy>
            <ixz>0</ixz>
            <iyy>0.145833</iyy>
            <iyz>0</iyz>
            <izz>0.125</izz>
          </inertia>
          <pose>0 0 0 0 -0 0</pose>
        </inertial>
        <collision name='collision'>
          <geometry>
            <cylinder>
              <radius>0.5</radius>
              <length>1</length>
            </cylinder>
          </geometry>
          <surface>
            <contact>
              <ode/>
            </contact>
            <bounce/>
            <friction>
              <torsional>
                <ode/>
              </torsional>
              <ode/>
            </friction>
          </surface>
          <max_contacts>10</max_contacts>
        </collision>
        <visual name='visual'>
          <geometry>
            <cylinder>
              <radius>0.5</radius>
              <length>1</length>
            </cylinder>
          </geometry>
          <material>
            <script>
              <name>Gazebo/Grey</name>
              <uri>file://media/materials/scripts/gazebo.material</uri>
            </script>
          </material>
        </visual>
        <self_collide>0</self_collide>
        <enable_wind>0</enable_wind>
        <kinematic>0</kinematic>
      </link>
    </model>
    <state world_name='default'>
      <sim_time>431 727000000</sim_time>
      <real_time>231 385312114</real_time>
      <wall_time>1731150753 632995640</wall_time>
      <iterations>174268</iterations>
      <model name='box_house'>
        <pose>-1.97643 0.05996 0 0 -0 0</pose>
        <scale>1 1 1</scale>
        <link name='Wall_1'>
          <pose>-1.97643 3.98496 0 0 -0 0</pose>
          <velocity>0 0 0 0 -0 0</velocity>
          <acceleration>0 0 0 0 -0 0</acceleration>
          <wrench>0 0 0 0 -0 0</wrench>
        </link>
        <link name='Wall_2'>
          <pose>4.44857 0.059964 0 0 0 -1.5708</pose>
          <velocity>0 0 0 0 -0 0</velocity>
          <acceleration>0 0 0 0 -0 0</acceleration>
          <wrench>0 0 0 0 -0 0</wrench>
        </link>
        <link name='Wall_3'>
          <pose>-1.97643 -3.86504 0 0 -0 3.14159</pose>
          <velocity>0 0 0 0 -0 0</velocity>
          <acceleration>0 0 0 0 -0 0</acceleration>
          <wrench>0 0 0 0 -0 0</wrench>
        </link>
        <link name='Wall_4'>
          <pose>-8.40143 0.059964 0 0 -0 1.5708</pose>
          <velocity>0 0 0 0 -0 0</velocity>
          <acceleration>0 0 0 0 -0 0</acceleration>
          <wrench>0 0 0 0 -0 0</wrench>
        </link>
      </model>
      <model name='ground_plane'>
        <pose>0 0 0 0 -0 0</pose>
        <scale>1 1 1</scale>
        <link name='link'>
          <pose>0 0 0 0 -0 0</pose>
          <velocity>0 0 0 0 -0 0</velocity>
          <acceleration>0 0 0 0 -0 0</acceleration>
          <wrench>0 0 0 0 -0 0</wrench>
        </link>
      </model>
      <model name='spibot'>
        <pose>-1e-06 4e-06 0.300001 6e-05 1.7e-05 1e-05</pose>
        <scale>1 1 1</scale>
        <link name='dummy'>
          <pose>-1e-06 4e-06 0.300001 6e-05 1.7e-05 1e-05</pose>
          <velocity>-0.002555 0.008027 0.001593 0.120359 0.036921 0.010682</velocity>
          <acceleration>0.151704 -0.910568 2.32144 -0.849438 -0.908379 -0.465044</acceleration>
          <wrench>0.442292 -2.65476 6.76815 0 -0 0</wrench>
        </link>
        <link name='hip1'>
          <pose>0.109989 -0.109991 0.411973 -0.001645 0.000673 -0.656437</pose>
          <velocity>-0.020307 0.016712 0.052734 -0.041174 -0.296343 0.078375</velocity>
          <acceleration>-45.5995 34.4462 109.352 1.70835 0.377888 -1.63139</acceleration>
          <wrench>-1.3886 1.04896 3.33 0 -0 0</wrench>
        </link>
        <link name='hip2'>
          <pose>0.110003 0.110015 0.411952 0.000134 0.00024 0.656479</pose>
          <velocity>0.007981 0.035106 -0.038453 0.103643 0.176991 -0.168367</velocity>
          <acceleration>21.8243 57.1762 -96.6596 -2.59515 0.751646 -2.08769</acceleration>
          <wrench>0.664593 1.74113 -2.94348 0 -0 0</wrench>
        </link>
        <link name='hip3'>
          <pose>-0.110247 0.110533 0.411144 0.009736 0.016688 2.13842</pose>
          <velocity>-0.102211 0.264535 -1.83355 0.435698 -1.09211 -1.41413</velocity>
          <acceleration>-219.194 1839.86 -7041.47 1.24236 -1.54578 1.87081</acceleration>
          <wrench>-6.67446 56.0238 -214.413 0 -0 0</wrench>
        </link>
        <link name='hip4'>
          <pose>-0.110025 -0.110008 0.411882 8e-05 -0.000298 -2.13791</pose>
          <velocity>-0.002398 -0.005862 -0.022618 0.09928 0.082759 0.208676</velocity>
          <acceleration>1.72183 -8.44863 -29.4423 2.00226 -0.940021 1.90469</acceleration>
          <wrench>0.05243 -0.257261 -0.896518 0 -0 0</wrench>
        </link>
        <link name='shank1'>
          <pose>0.321714 -0.274684 0.558573 -1.5767 1.27174 -0.662059</pose>
          <velocity>0.009786 0.01275 0.006031 -0.16561 -0.194601 0.068219</velocity>
          <acceleration>43.9861 -38.4208 -49.7706 -1.33997 1.44102 -2.5802</acceleration>
          <wrench>10.4201 -9.10171 -11.7904 0 -0 0</wrench>
        </link>
        <link name='shank2'>
          <pose>0.323308 0.272491 0.558719 -1.57121 1.27131 0.656101</pose>
          <velocity>-0.02301 -0.04703 0.065412 0.104493 -0.048798 -0.150135</velocity>
          <acceleration>-64.9864 -57.4435 60.2658 -0.811796 1.37255 2.14583</acceleration>
          <wrench>-15.3943 -13.6075 14.2761 0 -0 0</wrench>
        </link>
        <link name='shank3'>
          <pose>-0.27071 0.36558 0.458493 1.60846 1.45604 -0.967243</pose>
          <velocity>-0.635704 0.410749 4.38635 1.04966 -1.54015 -2.0293</velocity>
          <acceleration>3206.79 -3947.96 9592.39 1.6805 0.26444 2.44112</acceleration>
          <wrench>759.641 -935.212 2272.29 0 -0 0</wrench>
        </link>
        <link name='shank4'>
          <pose>-0.272355 -0.361713 0.457329 1.56985 1.49453 1.00198</pose>
          <velocity>0.030835 -0.03362 -0.008827 0.142504 -0.091363 0.122788</velocity>
          <acceleration>4.41337 12.1997 30.689 0.115749 -0.685572 -1.79015</acceleration>
          <wrench>1.04551 2.89005 7.27006 0 -0 0</wrench>
        </link>
        <link name='thigh1'>
          <pose>0.164555 -0.153867 0.441935 -1.57281 -0.531844 -0.655399</pose>
          <velocity>-0.022445 0.018317 0.055138 0.14462 0.200927 0.070045</velocity>
          <acceleration>-5.08299 7.58145 23.2381 0.718968 -1.29868 1.38494</acceleration>
          <wrench>-3.09335 4.61385 14.142 0 -0 0</wrench>
        </link>
        <link name='thigh2'>
          <pose>0.16637 0.151552 0.441911 -1.57093 -0.532702 0.656566</pose>
          <velocity>0.017265 0.028872 -0.066764 0.452576 -0.4953 -0.148557</velocity>
          <acceleration>-3.23431 5.10276 -36.1626 -0.33389 -1.11248 2.76128</acceleration>
          <wrench>-1.9683 3.10538 -22.0075 0 -0 0</wrench>
        </link>
        <link name='thigh3'>
          <pose>-0.147422 0.17161 0.438626 -1.57485 -0.08678 2.13694</pose>
          <velocity>-0.780551 1.31628 -6.96476 -1.24271 0.413048 1.15829</velocity>
          <acceleration>-1330.72 1630.49 -2489.65 1.0541 -0.546322 -0.766156</acceleration>
          <wrench>-809.839 992.268 -1515.13 0 -0 0</wrench>
        </link>
        <link name='thigh4'>
          <pose>-0.148932 -0.168254 0.441809 -1.57078 -0.067519 -2.13868</pose>
          <velocity>0.006245 -0.019687 -0.032632 -0.082863 0.061796 0.121592</velocity>
          <acceleration>-5.62972 -5.77594 -12.0154 2.60859 0.880778 -0.426657</acceleration>
          <wrench>-3.42608 -3.51506 -7.31223 0 -0 0</wrench>
        </link>
        <link name='vacuum_gripper1'>
          <pose>0.41924 -0.349746 0.159393 2.84253 0.00174 0.914382</pose>
          <velocity>0.092559 -0.046718 0.037452 -0.165552 -0.194481 0.068102</velocity>
          <acceleration>47.2649 -48.8531 -47.1554 -1.07318 -0.370836 2.3573</acceleration>
          <wrench>0.004726 -0.004885 -0.004716 0 -0 0</wrench>
        </link>
        <link name='vacuum_gripper2'>
          <pose>0.420503 0.348266 0.159592 2.84209 0.000124 2.2273</pose>
          <velocity>0.007893 -0.019916 0.078019 0.104309 -0.049318 -0.149573</velocity>
          <acceleration>-76.8506 -59.4867 57.0133 1.92647 -1.32909 1.8586</acceleration>
          <wrench>-0.007685 -0.005949 0.005701 0 -0 0</wrench>
        </link>
        <link name='vacuum_gripper3'>
          <pose>-0.244195 0.325793 0.043472 3.02692 -0.004323 0.566129</pose>
          <velocity>2.68477 -3.03447 4.91367 1.05746 -1.52887 -2.03682</velocity>
          <acceleration>5264.25 -6075.56 9881.41 -1.00929 1.49881 -2.07901</acceleration>
          <wrench>0.526425 -0.607556 0.988141 0 -0 0</wrench>
        </link>
        <link name='vacuum_gripper4'>
          <pose>-0.254579 -0.335301 0.040824 3.06532 6.7e-05 2.57371</pose>
          <velocity>0.065693 0.027904 -0.003391 0.142551 -0.091587 0.122745</velocity>
          <acceleration>9.26748 18.4494 31.3838 -3.11671 1.41363 -2.52652</acceleration>
          <wrench>0.000927 0.001845 0.003138 0 -0 0</wrench>
        </link>
      </model>
      <model name='traj_base'>
        <pose>0 0 -0 0 -0 0</pose>
        <scale>1 1 1</scale>
        <link name='root'>
          <pose>0 0 -0 0 -0 0</pose>
          <velocity>0 0 0 0 -0 0</velocity>
          <acceleration>0 0 -0 0 -0 0</acceleration>
          <wrench>0 0 -0 0 -0 0</wrench>
        </link>
      </model>
      <model name='unit_box'>
        <pose>-7.27142 3.09748 0.499995 1e-05 -0 0</pose>
        <scale>1 1 1</scale>
        <link name='link'>
          <pose>-7.27142 3.09748 0.499995 1e-05 -0 0</pose>
          <velocity>0 0 0 0 -0 0</velocity>
          <acceleration>-0.004709 -0.011055 -9.78158 0.022108 -0.009414 1e-06</acceleration>
          <wrench>-0.004709 -0.011055 -9.78158 0 -0 0</wrench>
        </link>
      </model>
      <model name='unit_box_0'>
        <pose>-4.96406 -2.00353 0.499995 0 1e-05 0</pose>
        <scale>1 1 1</scale>
        <link name='link'>
          <pose>-4.96406 -2.00353 0.499995 0 1e-05 0</pose>
          <velocity>0 0 0 0 -0 0</velocity>
          <acceleration>0.010615 -0.006191 -9.78231 0.012424 0.021225 1.8e-05</acceleration>
          <wrench>0.010615 -0.006191 -9.78231 0 -0 0</wrench>
        </link>
      </model>
      <model name='unit_box_1'>
        <pose>3.83311 3.3034 0.499995 1e-05 -0 0</pose>
        <scale>1 1 1</scale>
        <link name='link'>
          <pose>3.83311 3.3034 0.499995 1e-05 -0 0</pose>
          <velocity>0 0 0 0 -0 0</velocity>
          <acceleration>-0.004709 -0.011055 -9.78158 0.022108 -0.009414 1e-06</acceleration>
          <wrench>-0.004709 -0.011055 -9.78158 0 -0 0</wrench>
        </link>
      </model>
      <model name='unit_box_2'>
        <pose>-0.36 0.36 0.006667 3.4e-05 6e-06 -2e-06</pose>
        <scale>0.10251 0.071479 0.013331</scale>
        <link name='link'>
          <pose>-0.36 0.36 0.006667 3.4e-05 6e-06 -2e-06</pose>
          <velocity>0 0 0 0 -0 0</velocity>
          <acceleration>-0.019629 0.013687 -0.224267 1.08877 -0.197566 3.14159</acceleration>
          <wrench>-0.019629 0.013687 -0.224267 0 -0 0</wrench>
        </link>
      </model>
      <model name='unit_cylinder'>
        <pose>-4.57746 0.509884 0.499996 4e-06 3e-06 -0</pose>
        <scale>1 1 1</scale>
        <link name='link'>
          <pose>-4.57746 0.509884 0.499996 4e-06 3e-06 -0</pose>
          <velocity>0 0 0 0 -0 0</velocity>
          <acceleration>0 0 -9.8 0 -0 0</acceleration>
          <wrench>0 0 -9.8 0 -0 0</wrench>
        </link>
      </model>
      <model name='unit_cylinder_0'>
        <pose>-0.988143 2.12658 0.499992 -3e-06 2e-06 0</pose>
        <scale>1 1 1</scale>
        <link name='link'>
          <pose>-0.988143 2.12658 0.499992 -3e-06 2e-06 0</pose>
          <velocity>0 0 0 0 -0 0</velocity>
          <acceleration>0 0 -9.8 0 -0 0</acceleration>
          <wrench>0 0 -9.8 0 -0 0</wrench>
        </link>
      </model>
      <model name='unit_cylinder_1'>
        <pose>-0.890579 -1.90634 0.499998 3e-06 -2e-06 0</pose>
        <scale>1 1 1</scale>
        <link name='link'>
          <pose>-0.890579 -1.90634 0.499998 3e-06 -2e-06 0</pose>
          <velocity>0 0 0 0 -0 0</velocity>
          <acceleration>0 0 -9.8 0 -0 0</acceleration>
          <wrench>0 0 -9.8 0 -0 0</wrench>
        </link>
      </model>
      <light name='sun'>
        <pose>0 0 10 0 -0 0</pose>
      </light>
    </state>
    <gui fullscreen='0'>
      <camera name='user_camera'>
        <pose>-0.001375 -1.03828 0.728531 0 0.40764 1.59219</pose>
        <view_controller>orbit</view_controller>
        <projection_type>perspective</projection_type>
      </camera>
    </gui>
    <model name='unit_box_0'>
      <pose>-4.96407 -2.00354 0.5 0 -0 0</pose>
      <link name='link'>
        <inertial>
          <mass>1</mass>
          <inertia>
            <ixx>0.166667</ixx>
            <ixy>0</ixy>
            <ixz>0</ixz>
            <iyy>0.166667</iyy>
            <iyz>0</iyz>
            <izz>0.166667</izz>
          </inertia>
          <pose>0 0 0 0 -0 0</pose>
        </inertial>
        <collision name='collision'>
          <geometry>
            <box>
              <size>1 1 1</size>
            </box>
          </geometry>
          <surface>
            <contact>
              <ode/>
            </contact>
            <bounce/>
            <friction>
              <torsional>
                <ode/>
              </torsional>
              <ode/>
            </friction>
          </surface>
          <max_contacts>10</max_contacts>
        </collision>
        <visual name='visual'>
          <geometry>
            <box>
              <size>1 1 1</size>
            </box>
          </geometry>
          <material>
            <script>
              <name>Gazebo/Grey</name>
              <uri>file://media/materials/scripts/gazebo.material</uri>
            </script>
          </material>
        </visual>
        <self_collide>0</self_collide>
        <enable_wind>0</enable_wind>
        <kinematic>0</kinematic>
      </link>
    </model>
    <model name='unit_box_1'>
      <pose>3.83312 3.3034 0.5 0 -0 0</pose>
      <link name='link'>
        <inertial>
          <mass>1</mass>
          <inertia>
            <ixx>0.166667</ixx>
            <ixy>0</ixy>
            <ixz>0</ixz>
            <iyy>0.166667</iyy>
            <iyz>0</iyz>
            <izz>0.166667</izz>
          </inertia>
          <pose>0 0 0 0 -0 0</pose>
        </inertial>
        <collision name='collision'>
          <geometry>
            <box>
              <size>1 1 1</size>
            </box>
          </geometry>
          <surface>
            <contact>
              <ode/>
            </contact>
            <bounce/>
            <friction>
              <torsional>
                <ode/>
              </torsional>
              <ode/>
            </friction>
          </surface>
          <max_contacts>10</max_contacts>
        </collision>
        <visual name='visual'>
          <geometry>
            <box>
              <size>1 1 1</size>
            </box>
          </geometry>
          <material>
            <script>
              <name>Gazebo/Grey</name>
              <uri>file://media/materials/scripts/gazebo.material</uri>
            </script>
          </material>
        </visual>
        <self_collide>0</self_collide>
        <enable_wind>0</enable_wind>
        <kinematic>0</kinematic>
      </link>
    </model>
    <model name='unit_cylinder_0'>
      <pose>-0.988144 2.12658 0.5 0 -0 0</pose>
      <link name='link'>
        <inertial>
          <mass>1</mass>
          <inertia>
            <ixx>0.145833</ixx>
            <ixy>0</ixy>
            <ixz>0</ixz>
            <iyy>0.145833</iyy>
            <iyz>0</iyz>
            <izz>0.125</izz>
          </inertia>
          <pose>0 0 0 0 -0 0</pose>
        </inertial>
        <collision name='collision'>
          <geometry>
            <cylinder>
              <radius>0.5</radius>
              <length>1</length>
            </cylinder>
          </geometry>
          <surface>
            <contact>
              <ode/>
            </contact>
            <bounce/>
            <friction>
              <torsional>
                <ode/>
              </torsional>
              <ode/>
            </friction>
          </surface>
          <max_contacts>10</max_contacts>
        </collision>
        <visual name='visual'>
          <geometry>
            <cylinder>
              <radius>0.5</radius>
              <length>1</length>
            </cylinder>
          </geometry>
          <material>
            <script>
              <name>Gazebo/Grey</name>
              <uri>file://media/materials/scripts/gazebo.material</uri>
            </script>
          </material>
        </visual>
        <self_collide>0</self_collide>
        <enable_wind>0</enable_wind>
        <kinematic>0</kinematic>
      </link>
    </model>
    <model name='unit_cylinder_1'>
      <pose>-0.890578 -1.90634 0.5 0 -0 0</pose>
      <link name='link'>
        <inertial>
          <mass>1</mass>
          <inertia>
            <ixx>0.145833</ixx>
            <ixy>0</ixy>
            <ixz>0</ixz>
            <iyy>0.145833</iyy>
            <iyz>0</iyz>
            <izz>0.125</izz>
          </inertia>
          <pose>0 0 0 0 -0 0</pose>
        </inertial>
        <collision name='collision'>
          <geometry>
            <cylinder>
              <radius>0.5</radius>
              <length>1</length>
            </cylinder>
          </geometry>
          <surface>
            <contact>
              <ode/>
            </contact>
            <bounce/>
            <friction>
              <torsional>
                <ode/>
              </torsional>
              <ode/>
            </friction>
          </surface>
          <max_contacts>10</max_contacts>
        </collision>
        <visual name='visual'>
          <geometry>
            <cylinder>
              <radius>0.5</radius>
              <length>1</length>
            </cylinder>
          </geometry>
          <material>
            <script>
              <name>Gazebo/Grey</name>
              <uri>file://media/materials/scripts/gazebo.material</uri>
            </script>
          </material>
        </visual>
        <self_collide>0</self_collide>
        <enable_wind>0</enable_wind>
        <kinematic>0</kinematic>
      </link>
    </model>
    <model name='spibot'>
      <joint name='base_static_joint' type='fixed'>
        <pose relative_to='__model__'>0 0 0 0 -0 0</pose>
        <parent>world</parent>
        <child>dummy</child>
      </joint>
      <link name='dummy'>
        <pose relative_to='base_static_joint'>0 0 0 0 -0 0</pose>
        <inertial>
          <pose>9.8e-05 -0.003576 0.070445 0 -0 0</pose>
          <mass>2.9155</mass>
          <inertia>
            <ixx>0.00671889</ixx>
            <ixy>6.28446e-06</ixy>
            <ixz>-7.58536e-07</ixz>
            <iyy>0.00689751</iyy>
            <iyz>0.000519704</iyz>
            <izz>0.010494</izz>
          </inertia>
        </inertial>
        <collision name='dummy_fixed_joint_lump__base_link_collision'>
          <pose>0 0 0 0 -0 0</pose>
          <geometry>
            <mesh>
              <scale>1 1 1</scale>
              <uri>/root/spibot_ws/src/sipder_robot/meshes/base_link.STL</uri>
            </mesh>
          </geometry>
          <surface>
            <contact>
              <ode/>
            </contact>
            <friction>
              <ode/>
              <torsional>
                <ode/>
              </torsional>
            </friction>
            <bounce/>
          </surface>
          <max_contacts>10</max_contacts>
        </collision>
        <collision name='dummy_fixed_joint_lump__camera_collision_1'>
          <pose>0.000633 0.17702 0.084 0 -0 1.57</pose>
          <geometry>
            <mesh>
              <scale>1 1 1</scale>
              <uri>/root/spibot_ws/src/sipder_robot/meshes/camera.STL</uri>
            </mesh>
          </geometry>
          <surface>
            <contact>
              <ode/>
            </contact>
            <friction>
              <ode/>
              <torsional>
                <ode/>
              </torsional>
            </friction>
            <bounce/>
          </surface>
          <max_contacts>10</max_contacts>
        </collision>
        <collision name='dummy_fixed_joint_lump__lidar_collision_2'>
          <pose>8.7e-05 0.038511 -0.000556 3.14159 -0 -3.14159</pose>
          <geometry>
            <mesh>
              <scale>1 1 1</scale>
              <uri>/root/spibot_ws/src/sipder_robot/meshes/lidar.STL</uri>
            </mesh>
          </geometry>
          <surface>
            <contact>
              <ode/>
            </contact>
            <friction>
              <ode/>
              <torsional>
                <ode/>
              </torsional>
            </friction>
            <bounce/>
          </surface>
          <max_contacts>10</max_contacts>
        </collision>
        <visual name='dummy_visual'>
          <pose>0 0 0 0 -0 0</pose>
          <geometry>
            <box>
              <size>0.001 0.001 0.001</size>
            </box>
          </geometry>
        </visual>
        <visual name='dummy_fixed_joint_lump__base_link_visual_1'>
          <pose>0 0 0 0 -0 0</pose>
          <geometry>
            <mesh>
              <scale>1 1 1</scale>
              <uri>/root/spibot_ws/src/sipder_robot/meshes/base_link.STL</uri>
            </mesh>
          </geometry>
          <material>
            <script>
              <name>Gazebo/White</name>
              <uri>file://media/materials/scripts/gazebo.material</uri>
            </script>
          </material>
        </visual>
        <visual name='dummy_fixed_joint_lump__camera_visual_2'>
          <pose>0.000633 0.17702 0.084 0 -0 1.57</pose>
          <geometry>
            <mesh>
              <scale>1 1 1</scale>
              <uri>/root/spibot_ws/src/sipder_robot/meshes/camera.STL</uri>
            </mesh>
          </geometry>
          <material>
            <script>
              <name>Gazebo/DarkGrey</name>
              <uri>file://media/materials/scripts/gazebo.material</uri>
            </script>
          </material>
        </visual>
        <visual name='dummy_fixed_joint_lump__lidar_visual_3'>
          <pose>8.7e-05 0.038511 -0.000556 3.14159 -0 -3.14159</pose>
          <geometry>
            <mesh>
              <scale>1 1 1</scale>
              <uri>/root/spibot_ws/src/sipder_robot/meshes/lidar.STL</uri>
            </mesh>
          </geometry>
          <material>
            <script>
              <name>Gazebo/Indigo</name>
              <uri>file://media/materials/scripts/gazebo.material</uri>
            </script>
          </material>
        </visual>
        <sensor name='depth_camera' type='depth'>
          <always_on>1</always_on>
          <update_rate>20</update_rate>
          <camera>
            <horizontal_fov>1.57</horizontal_fov>
            <image>
              <format>R8G8B8</format>
              <width>640</width>
              <height>480</height>
            </image>
            <clip>
              <near>0.05</near>
              <far>8</far>
            </clip>
          </camera>
          <plugin name='kinect_camera_controller' filename='libgazebo_ros_openni_kinect.so'>
            <cameraName>depth_camera</cameraName>
            <alwaysOn>1</alwaysOn>
            <updateRate>10</updateRate>
            <imageTopicName>rgb/image_raw</imageTopicName>
            <depthImageTopicName>depth/image_raw</depthImageTopicName>
            <pointCloudTopicName>depth/points</pointCloudTopicName>
            <cameraInfoTopicName>rgb/camera_info</cameraInfoTopicName>
            <depthImageCameraInfoTopicName>depth/camera_info</depthImageCameraInfoTopicName>
            <frameName>camera</frameName>
            <baseline>0.1</baseline>
            <distortion_k1>0.0</distortion_k1>
            <distortion_k2>0.0</distortion_k2>
            <distortion_k3>0.0</distortion_k3>
            <distortion_t1>0.0</distortion_t1>
            <distortion_t2>0.0</distortion_t2>
            <pointCloudCutoff>0.4</pointCloudCutoff>
            <robotNamespace>/</robotNamespace>
          </plugin>
          <pose>0.000633 0.17702 0.084 0 -0 1.57</pose>
        </sensor>
        <gravity>1</gravity>
        <sensor name='imu_sensor' type='imu'>
          <always_on>1</always_on>
          <update_rate>100</update_rate>
          <visualize>1</visualize>
          <topic>__default_topic__</topic>
          <plugin name='imu_plugin' filename='libgazebo_ros_imu_sensor.so'>
            <topicName>imu/data</topicName>
            <bodyName>camera</bodyName>
            <updateRateHZ>100.0</updateRateHZ>
            <gaussianNoise>0.0</gaussianNoise>
            <xyzOffset>0 0 0</xyzOffset>
            <rpyOffset>0 0 0</rpyOffset>
            <frameName>imu_link</frameName>
            <robotNamespace>/</robotNamespace>
          </plugin>
          <pose>0.000633 0.17702 0.084 0 -0 1.57</pose>
          <imu/>
        </sensor>
        <self_collide>0</self_collide>
        <enable_wind>0</enable_wind>
        <kinematic>0</kinematic>
      </link>
      <joint name='base2hip1' type='revolute'>
        <pose relative_to='dummy'>0.11 -0.11 0.112 0 -0 0</pose>
        <parent>dummy</parent>
        <child>hip1</child>
        <axis>
          <xyz>0 0 1</xyz>
          <limit>
            <lower>-1.57</lower>
            <upper>1.57</upper>
            <effort>500</effort>
            <velocity>40</velocity>
          </limit>
          <dynamics>
            <spring_reference>0</spring_reference>
            <spring_stiffness>0</spring_stiffness>
          </dynamics>
        </axis>
      </joint>
      <link name='hip1'>
        <pose relative_to='base2hip1'>0 0 0 0 -0 0</pose>
        <inertial>
          <pose>0.030542 -0.027829 0.01669 0 -0 0</pose>
          <mass>0.030452</mass>
          <inertia>
            <ixx>1.0281e-05</ixx>
            <ixy>9.4587e-07</ixy>
            <ixz>-3.6642e-06</ixz>
            <iyy>2.4586e-05</iyy>
            <iyz>7.6559e-07</iyz>
            <izz>2.3255e-05</izz>
          </inertia>
        </inertial>
        <collision name='hip1_collision'>
          <pose>0 0 0 0 -0 0</pose>
          <geometry>
            <mesh>
              <scale>1 1 1</scale>
              <uri>/root/spibot_ws/src/sipder_robot/meshes/hip1.STL</uri>
            </mesh>
          </geometry>
          <surface>
            <contact>
              <ode/>
            </contact>
            <friction>
              <ode>
                <mu>0.3</mu>
                <mu2>0.3</mu2>
              </ode>
              <torsional>
                <ode/>
              </torsional>
            </friction>
            <bounce/>
          </surface>
          <max_contacts>10</max_contacts>
        </collision>
        <visual name='hip1_visual'>
          <pose>0 0 0 0 -0 0</pose>
          <geometry>
            <mesh>
              <scale>1 1 1</scale>
              <uri>/root/spibot_ws/src/sipder_robot/meshes/hip1.STL</uri>
            </mesh>
          </geometry>
          <material>
            <script>
              <name>Gazebo/RedBright</name>
              <uri>file://media/materials/scripts/gazebo.material</uri>
            </script>
          </material>
        </visual>
        <self_collide>0</self_collide>
        <enable_wind>0</enable_wind>
        <kinematic>0</kinematic>
      </link>
      <joint name='hip2thigh1' type='revolute'>
        <pose relative_to='hip1'>0.07 -0.0015 0.03 -1.5708 0 0</pose>
        <parent>hip1</parent>
        <child>thigh1</child>
        <axis>
          <xyz>0 0 1</xyz>
          <limit>
            <lower>-3.14</lower>
            <upper>3.14</upper>
            <effort>500</effort>
            <velocity>40</velocity>
          </limit>
          <dynamics>
            <spring_reference>0</spring_reference>
            <spring_stiffness>0</spring_stiffness>
          </dynamics>
        </axis>
      </joint>
      <link name='thigh1'>
        <pose relative_to='hip2thigh1'>0 0 0 0 -0 0</pose>
        <inertial>
          <pose>0.11489 9.5e-05 -0.005688 0 -0 0</pose>
          <mass>0.60857</mass>
          <inertia>
            <ixx>0.0002871</ixx>
            <ixy>-1.1416e-07</ixy>
            <ixz>-4.4479e-08</ixz>
            <iyy>0.0013103</iyy>
            <iyz>8.1337e-08</iyz>
            <izz>0.0015428</izz>
          </inertia>
        </inertial>
        <collision name='thigh1_collision'>
          <pose>0 0 0 0 -0 0</pose>
          <geometry>
            <mesh>
              <scale>1 1 1</scale>
              <uri>/root/spibot_ws/src/sipder_robot/meshes/thigh1.STL</uri>
            </mesh>
          </geometry>
          <surface>
            <contact>
              <ode/>
            </contact>
            <friction>
              <ode>
                <mu>0.3</mu>
                <mu2>0.3</mu2>
              </ode>
              <torsional>
                <ode/>
              </torsional>
            </friction>
            <bounce/>
          </surface>
          <max_contacts>10</max_contacts>
        </collision>
        <visual name='thigh1_visual'>
          <pose>0 0 0 0 -0 0</pose>
          <geometry>
            <mesh>
              <scale>1 1 1</scale>
              <uri>/root/spibot_ws/src/sipder_robot/meshes/thigh1.STL</uri>
            </mesh>
          </geometry>
          <material>
            <script>
              <name>Gazebo/Green</name>
              <uri>file://media/materials/scripts/gazebo.material</uri>
            </script>
          </material>
        </visual>
        <self_collide>1</self_collide>
        <enable_wind>0</enable_wind>
        <kinematic>0</kinematic>
      </link>
      <joint name='thigh2shank1' type='revolute'>
        <pose relative_to='thigh1'>0.23 0 0 0 -0 1.5708</pose>
        <parent>thigh1</parent>
        <child>shank1</child>
        <axis>
          <xyz>0 0 1</xyz>
          <limit>
            <lower>-3.14</lower>
            <upper>3.14</upper>
            <effort>500</effort>
            <velocity>40</velocity>
          </limit>
          <dynamics>
            <spring_reference>0</spring_reference>
            <spring_stiffness>0</spring_stiffness>
          </dynamics>
        </axis>
      </joint>
      <link name='shank1'>
        <pose relative_to='thigh2shank1'>0 0 0 0 -0 0</pose>
        <inertial>
          <pose>0.2884 2e-06 -0.003003 0 -0 0</pose>
          <mass>0.236895</mass>
          <inertia>
            <ixx>0.000187737</ixx>
            <ixy>-4.92161e-08</ixy>
            <ixz>-0.000139609</ixz>
            <iyy>0.00351775</iyy>
            <iyz>-6.97624e-09</iyz>
            <izz>0.00351833</izz>
          </inertia>
        </inertial>
        <collision name='shank1_collision'>
          <pose>0 0 0 0 -0 0</pose>
          <geometry>
            <mesh>
              <scale>1 1 1</scale>
              <uri>/root/spibot_ws/src/sipder_robot/meshes/shank1.STL</uri>
            </mesh>
          </geometry>
          <surface>
            <contact>
              <ode/>
            </contact>
            <friction>
              <ode>
                <mu>0.3</mu>
                <mu2>0.3</mu2>
              </ode>
              <torsional>
                <ode/>
              </torsional>
            </friction>
            <bounce/>
          </surface>
          <max_contacts>10</max_contacts>
        </collision>
        <collision name='shank1_fixed_joint_lump__foot1_collision_collision_1'>
          <pose>0.36572 0 0.00075 -3e-06 -1.57079 3.14159</pose>
          <geometry>
            <mesh>
              <scale>1 1 1</scale>
              <uri>/root/spibot_ws/src/sipder_robot/meshes/foot1.STL</uri>
            </mesh>
          </geometry>
          <surface>
            <contact>
              <ode/>
            </contact>
            <friction>
              <ode>
                <mu>1</mu>
                <mu2>1</mu2>
              </ode>
              <torsional>
                <ode/>
              </torsional>
            </friction>
            <bounce/>
          </surface>
          <max_contacts>10</max_contacts>
        </collision>
        <visual name='shank1_visual'>
          <pose>0 0 0 0 -0 0</pose>
          <geometry>
            <mesh>
              <scale>1 1 1</scale>
              <uri>/root/spibot_ws/src/sipder_robot/meshes/shank1.STL</uri>
            </mesh>
          </geometry>
          <material>
            <script>
              <name>Gazebo/Turquoise</name>
              <uri>file://media/materials/scripts/gazebo.material</uri>
            </script>
          </material>
        </visual>
        <visual name='shank1_fixed_joint_lump__foot1_visual_1'>
          <pose>0.36572 0 0.00075 -3e-06 -1.57079 3.14159</pose>
          <geometry>
            <mesh>
              <scale>1 1 1</scale>
              <uri>/root/spibot_ws/src/sipder_robot/meshes/foot1.STL</uri>
            </mesh>
          </geometry>
          <material>
            <script>
              <name>Gazebo/SkyBlue</name>
              <uri>file://media/materials/scripts/gazebo.material</uri>
            </script>
          </material>
        </visual>
        <self_collide>1</self_collide>
        <self_collide>1</self_collide>
        <enable_wind>0</enable_wind>
        <kinematic>0</kinematic>
      </link>
      <joint name='gripper1_joint' type='revolute'>
        <pose relative_to='shank1'>0.41772 -0 0.00075 1.55979 -1.57079 1.58179</pose>
        <parent>shank1</parent>
        <child>vacuum_gripper1</child>
        <axis>
          <xyz>1 0 0</xyz>
          <limit>
            <lower>0</lower>
            <upper>0</upper>
            <effort>50</effort>
            <velocity>50</velocity>
          </limit>
          <dynamics>
            <damping>0</damping>
            <friction>10</friction>
            <spring_reference>0</spring_reference>
            <spring_stiffness>0</spring_stiffness>
          </dynamics>
        </axis>
      </joint>
      <link name='vacuum_gripper1'>
        <pose relative_to='gripper1_joint'>0 0 0 0 -0 0</pose>
        <inertial>
          <pose>0 0 0 0 -0 0</pose>
          <mass>0.0001</mass>
          <inertia>
            <ixx>1e-08</ixx>
            <ixy>0</ixy>
            <ixz>0</ixz>
            <iyy>1e-08</iyy>
            <iyz>0</iyz>
            <izz>1e-08</izz>
          </inertia>
        </inertial>
        <visual name='vacuum_gripper1_visual'>
          <pose>0 0 0 0 -0 0</pose>
          <geometry>
            <cylinder>
              <length>0.01</length>
              <radius>0.05</radius>
            </cylinder>
          </geometry>
          <material>
            <script>
              <name>Gazebo/Grey</name>
              <uri>file://media/materials/scripts/gazebo.material</uri>
            </script>
          </material>
        </visual>
        <self_collide>0</self_collide>
        <enable_wind>0</enable_wind>
        <kinematic>0</kinematic>
      </link>
      <joint name='base2hip2' type='revolute'>
        <pose relative_to='dummy'>0.11 0.11 0.112 0 -0 0</pose>
        <parent>dummy</parent>
        <child>hip2</child>
        <axis>
          <xyz>0 0 -1</xyz>
          <limit>
            <lower>-1.57</lower>
            <upper>1.57</upper>
            <effort>500</effort>
            <velocity>40</velocity>
          </limit>
          <dynamics>
            <spring_reference>0</spring_reference>
            <spring_stiffness>0</spring_stiffness>
          </dynamics>
        </axis>
      </joint>
      <link name='hip2'>
        <pose relative_to='base2hip2'>0 0 0 0 -0 0</pose>
        <inertial>
          <pose>0.030542 -0.0278 0.01669 0 -0 0</pose>
          <mass>0.030452</mass>
          <inertia>
            <ixx>1.02808e-05</ixx>
            <ixy>9.45875e-07</ixy>
            <ixz>-3.66419e-06</ixz>
            <iyy>2.45864e-05</iyy>
            <iyz>7.65596e-07</iyz>
            <izz>2.32546e-05</izz>
          </inertia>
        </inertial>
        <collision name='hip2_collision'>
          <pose>0 0 0 0 -0 0</pose>
          <geometry>
            <mesh>
              <scale>1 1 1</scale>
              <uri>/root/spibot_ws/src/sipder_robot/meshes/hip2.STL</uri>
            </mesh>
          </geometry>
          <surface>
            <contact>
              <ode/>
            </contact>
            <friction>
              <ode>
                <mu>0.3</mu>
                <mu2>0.3</mu2>
              </ode>
              <torsional>
                <ode/>
              </torsional>
            </friction>
            <bounce/>
          </surface>
          <max_contacts>10</max_contacts>
        </collision>
        <visual name='hip2_visual'>
          <pose>0 0 0 0 -0 0</pose>
          <geometry>
            <mesh>
              <scale>1 1 1</scale>
              <uri>/root/spibot_ws/src/sipder_robot/meshes/hip2.STL</uri>
            </mesh>
          </geometry>
          <material>
            <script>
              <name>Gazebo/RedBright</name>
              <uri>file://media/materials/scripts/gazebo.material</uri>
            </script>
          </material>
        </visual>
        <self_collide>0</self_collide>
        <enable_wind>0</enable_wind>
        <kinematic>0</kinematic>
      </link>
      <joint name='hip2thigh2' type='revolute'>
        <pose relative_to='hip2'>0.07 -0.0015 0.03 -1.5708 0 0</pose>
        <parent>hip2</parent>
        <child>thigh2</child>
        <axis>
          <xyz>0 0 -1</xyz>
          <limit>
            <lower>-3.14</lower>
            <upper>3.14</upper>
            <effort>500</effort>
            <velocity>40</velocity>
          </limit>
          <dynamics>
            <spring_reference>0</spring_reference>
            <spring_stiffness>0</spring_stiffness>
          </dynamics>
        </axis>
      </joint>
      <link name='thigh2'>
        <pose relative_to='hip2thigh2'>0 0 0 0 -0 0</pose>
        <inertial>
          <pose>0.11489 9.5e-05 -0.005688 0 -0 0</pose>
          <mass>0.60857</mass>
          <inertia>
            <ixx>0.0002871</ixx>
            <ixy>-1.1416e-07</ixy>
            <ixz>-4.4479e-08</ixz>
            <iyy>0.0013103</iyy>
            <iyz>8.1337e-08</iyz>
            <izz>0.0015428</izz>
          </inertia>
        </inertial>
        <collision name='thigh2_collision'>
          <pose>0 0 0 0 -0 0</pose>
          <geometry>
            <mesh>
              <scale>1 1 1</scale>
              <uri>/root/spibot_ws/src/sipder_robot/meshes/thigh2.STL</uri>
            </mesh>
          </geometry>
          <surface>
            <contact>
              <ode/>
            </contact>
            <friction>
              <ode>
                <mu>0.3</mu>
                <mu2>0.3</mu2>
              </ode>
              <torsional>
                <ode/>
              </torsional>
            </friction>
            <bounce/>
          </surface>
          <max_contacts>10</max_contacts>
        </collision>
        <visual name='thigh2_visual'>
          <pose>0 0 0 0 -0 0</pose>
          <geometry>
            <mesh>
              <scale>1 1 1</scale>
              <uri>/root/spibot_ws/src/sipder_robot/meshes/thigh2.STL</uri>
            </mesh>
          </geometry>
          <material>
            <script>
              <name>Gazebo/Green</name>
              <uri>file://media/materials/scripts/gazebo.material</uri>
            </script>
          </material>
        </visual>
        <self_collide>1</self_collide>
        <enable_wind>0</enable_wind>
        <kinematic>0</kinematic>
      </link>
      <joint name='thigh2shank2' type='revolute'>
        <pose relative_to='thigh2'>0.23 0 0 0 -0 1.5708</pose>
        <parent>thigh2</parent>
        <child>shank2</child>
        <axis>
          <xyz>0 0 1</xyz>
          <limit>
            <lower>-3.14</lower>
            <upper>3.14</upper>
            <effort>500</effort>
            <velocity>40</velocity>
          </limit>
          <dynamics>
            <spring_reference>0</spring_reference>
            <spring_stiffness>0</spring_stiffness>
          </dynamics>
        </axis>
      </joint>
      <link name='shank2'>
        <pose relative_to='thigh2shank2'>0 0 0 0 -0 0</pose>
        <inertial>
          <pose>0.288397 0 -0.003004 0 -0 0</pose>
          <mass>0.236885</mass>
          <inertia>
            <ixx>0.000187736</ixx>
            <ixy>-5.77658e-09</ixy>
            <ixz>-0.000139591</ixz>
            <iyy>0.00472453</iyy>
            <iyz>-6.70905e-09</iyz>
            <izz>0.00351832</izz>
          </inertia>
        </inertial>
        <collision name='shank2_collision'>
          <pose>0 0 0 0 -0 0</pose>
          <geometry>
            <mesh>
              <scale>1 1 1</scale>
              <uri>/root/spibot_ws/src/sipder_robot/meshes/shank2.STL</uri>
            </mesh>
          </geometry>
          <surface>
            <contact>
              <ode/>
            </contact>
            <friction>
              <ode>
                <mu>0.3</mu>
                <mu2>0.3</mu2>
              </ode>
              <torsional>
                <ode/>
              </torsional>
            </friction>
            <bounce/>
          </surface>
          <max_contacts>10</max_contacts>
        </collision>
        <collision name='shank2_fixed_joint_lump__foot2_collision_collision_1'>
          <pose>0.36572 0 0.00075 -3e-06 -1.57079 3.14159</pose>
          <geometry>
            <mesh>
              <scale>1 1 1</scale>
              <uri>/root/spibot_ws/src/sipder_robot/meshes/foot2.STL</uri>
            </mesh>
          </geometry>
          <surface>
            <contact>
              <ode/>
            </contact>
            <friction>
              <ode>
                <mu>1</mu>
                <mu2>1</mu2>
              </ode>
              <torsional>
                <ode/>
              </torsional>
            </friction>
            <bounce/>
          </surface>
          <max_contacts>10</max_contacts>
        </collision>
        <visual name='shank2_visual'>
          <pose>0 0 0 0 -0 0</pose>
          <geometry>
            <mesh>
              <scale>1 1 1</scale>
              <uri>/root/spibot_ws/src/sipder_robot/meshes/shank2.STL</uri>
            </mesh>
          </geometry>
          <material>
            <script>
              <name>Gazebo/Turquoise</name>
              <uri>file://media/materials/scripts/gazebo.material</uri>
            </script>
          </material>
        </visual>
        <visual name='shank2_fixed_joint_lump__foot2_visual_1'>
          <pose>0.36572 0 0.00075 -3e-06 -1.57079 3.14159</pose>
          <geometry>
            <mesh>
              <scale>1 1 1</scale>
              <uri>/root/spibot_ws/src/sipder_robot/meshes/foot2.STL</uri>
            </mesh>
          </geometry>
          <material>
            <script>
              <name>Gazebo/SkyBlue</name>
              <uri>file://media/materials/scripts/gazebo.material</uri>
            </script>
          </material>
        </visual>
        <self_collide>1</self_collide>
        <self_collide>1</self_collide>
        <enable_wind>0</enable_wind>
        <kinematic>0</kinematic>
      </link>
      <joint name='gripper2_joint' type='revolute'>
        <pose relative_to='shank2'>0.41772 -0 0.00075 1.56979 -1.57079 1.57179</pose>
        <parent>shank2</parent>
        <child>vacuum_gripper2</child>
        <axis>
          <xyz>1 0 0</xyz>
          <limit>
            <lower>0</lower>
            <upper>0</upper>
            <effort>50</effort>
            <velocity>50</velocity>
          </limit>
          <dynamics>
            <damping>0</damping>
            <friction>10</friction>
            <spring_reference>0</spring_reference>
            <spring_stiffness>0</spring_stiffness>
          </dynamics>
        </axis>
      </joint>
      <link name='vacuum_gripper2'>
        <pose relative_to='gripper2_joint'>0 0 0 0 -0 0</pose>
        <inertial>
          <pose>0 0 0 0 -0 0</pose>
          <mass>0.0001</mass>
          <inertia>
            <ixx>1e-08</ixx>
            <ixy>0</ixy>
            <ixz>0</ixz>
            <iyy>1e-08</iyy>
            <iyz>0</iyz>
            <izz>1e-08</izz>
          </inertia>
        </inertial>
        <visual name='vacuum_gripper2_visual'>
          <pose>0 0 0 0 -0 0</pose>
          <geometry>
            <cylinder>
              <length>0.01</length>
              <radius>0.05</radius>
            </cylinder>
          </geometry>
          <material>
            <script>
              <name>Gazebo/Grey</name>
              <uri>file://media/materials/scripts/gazebo.material</uri>
            </script>
          </material>
        </visual>
        <self_collide>0</self_collide>
        <enable_wind>0</enable_wind>
        <kinematic>0</kinematic>
      </link>
      <joint name='base2hip3' type='revolute'>
        <pose relative_to='dummy'>-0.11 0.11 0.112 0 0 -3.14159</pose>
        <parent>dummy</parent>
        <child>hip3</child>
        <axis>
          <xyz>0 0 1</xyz>
          <limit>
            <lower>-1.57</lower>
            <upper>1.57</upper>
            <effort>500</effort>
            <velocity>40</velocity>
          </limit>
          <dynamics>
            <spring_reference>0</spring_reference>
            <spring_stiffness>0</spring_stiffness>
          </dynamics>
        </axis>
      </joint>
      <link name='hip3'>
        <pose relative_to='base2hip3'>0 0 0 0 -0 0</pose>
        <inertial>
          <pose>0.03054 -0.0278 0.01669 0 -0 0</pose>
          <mass>0.03045</mass>
          <inertia>
            <ixx>1.02808e-05</ixx>
            <ixy>9.45871e-07</ixy>
            <ixz>-3.66419e-06</ixz>
            <iyy>2.45864e-05</iyy>
            <iyz>7.65591e-07</iyz>
            <izz>2.32546e-05</izz>
          </inertia>
        </inertial>
        <collision name='hip3_collision'>
          <pose>0 0 0 0 -0 0</pose>
          <geometry>
            <mesh>
              <scale>1 1 1</scale>
              <uri>/root/spibot_ws/src/sipder_robot/meshes/hip3.STL</uri>
            </mesh>
          </geometry>
          <surface>
            <contact>
              <ode/>
            </contact>
            <friction>
              <ode>
                <mu>0.3</mu>
                <mu2>0.3</mu2>
              </ode>
              <torsional>
                <ode/>
              </torsional>
            </friction>
            <bounce/>
          </surface>
          <max_contacts>10</max_contacts>
        </collision>
        <visual name='hip3_visual'>
          <pose>0 0 0 0 -0 0</pose>
          <geometry>
            <mesh>
              <scale>1 1 1</scale>
              <uri>/root/spibot_ws/src/sipder_robot/meshes/hip3.STL</uri>
            </mesh>
          </geometry>
          <material>
            <script>
              <name>Gazebo/RedBright</name>
              <uri>file://media/materials/scripts/gazebo.material</uri>
            </script>
          </material>
        </visual>
        <self_collide>0</self_collide>
        <enable_wind>0</enable_wind>
        <kinematic>0</kinematic>
      </link>
      <joint name='hip2thigh3' type='revolute'>
        <pose relative_to='hip3'>0.07 -0.0015 0.03 -1.5708 0 0</pose>
        <parent>hip3</parent>
        <child>thigh3</child>
        <axis>
          <xyz>0 0 -1</xyz>
          <limit>
            <lower>-3.14</lower>
            <upper>3.14</upper>
            <effort>500</effort>
            <velocity>40</velocity>
          </limit>
          <dynamics>
            <spring_reference>0</spring_reference>
            <spring_stiffness>0</spring_stiffness>
          </dynamics>
        </axis>
      </joint>
      <link name='thigh3'>
        <pose relative_to='hip2thigh3'>0 0 0 0 -0 0</pose>
        <inertial>
          <pose>0.11489 9.5e-05 -0.005688 0 -0 0</pose>
          <mass>0.60857</mass>
          <inertia>
            <ixx>0.0002871</ixx>
            <ixy>-1.1416e-07</ixy>
            <ixz>-4.4479e-08</ixz>
            <iyy>0.0013103</iyy>
            <iyz>8.1337e-08</iyz>
            <izz>0.0015428</izz>
          </inertia>
        </inertial>
        <collision name='thigh3_collision'>
          <pose>0 0 0 0 -0 0</pose>
          <geometry>
            <mesh>
              <scale>1 1 1</scale>
              <uri>/root/spibot_ws/src/sipder_robot/meshes/thigh3.STL</uri>
            </mesh>
          </geometry>
          <surface>
            <contact>
              <ode/>
            </contact>
            <friction>
              <ode>
                <mu>0.3</mu>
                <mu2>0.3</mu2>
              </ode>
              <torsional>
                <ode/>
              </torsional>
            </friction>
            <bounce/>
          </surface>
          <max_contacts>10</max_contacts>
        </collision>
        <visual name='thigh3_visual'>
          <pose>0 0 0 0 -0 0</pose>
          <geometry>
            <mesh>
              <scale>1 1 1</scale>
              <uri>/root/spibot_ws/src/sipder_robot/meshes/thigh3.STL</uri>
            </mesh>
          </geometry>
          <material>
            <script>
              <name>Gazebo/Green</name>
              <uri>file://media/materials/scripts/gazebo.material</uri>
            </script>
          </material>
        </visual>
        <self_collide>1</self_collide>
        <enable_wind>0</enable_wind>
        <kinematic>0</kinematic>
      </link>
      <joint name='thigh2shank3' type='revolute'>
        <pose relative_to='thigh3'>0.23 0 0 0 -0 1.5708</pose>
        <parent>thigh3</parent>
        <child>shank3</child>
        <axis>
          <xyz>0 0 -1</xyz>
          <limit>
            <lower>-3.14</lower>
            <upper>3.14</upper>
            <effort>500</effort>
            <velocity>40</velocity>
          </limit>
          <dynamics>
            <spring_reference>0</spring_reference>
            <spring_stiffness>0</spring_stiffness>
          </dynamics>
        </axis>
      </joint>
      <link name='shank3'>
        <pose relative_to='thigh2shank3'>0 0 0 0 -0 0</pose>
        <inertial>
          <pose>0.288396 -4e-06 -0.002999 0 -0 0</pose>
          <mass>0.236885</mass>
          <inertia>
            <ixx>0.000187745</ixx>
            <ixy>7.70467e-08</ixy>
            <ixz>-0.000139696</ixz>
            <iyy>0.0035177</iyy>
            <iyz>5.87769e-09</iyz>
            <izz>0.00351828</izz>
          </inertia>
        </inertial>
        <collision name='shank3_collision'>
          <pose>0 0 0 0 -0 0</pose>
          <geometry>
            <mesh>
              <scale>1 1 1</scale>
              <uri>/root/spibot_ws/src/sipder_robot/meshes/shank3.STL</uri>
            </mesh>
          </geometry>
          <surface>
            <contact>
              <ode/>
            </contact>
            <friction>
              <ode>
                <mu>0.3</mu>
                <mu2>0.3</mu2>
              </ode>
              <torsional>
                <ode/>
              </torsional>
            </friction>
            <bounce/>
          </surface>
          <max_contacts>10</max_contacts>
        </collision>
        <collision name='shank3_fixed_joint_lump__foot3_collision_collision_1'>
          <pose>0.36572 0 0.00075 3.14159 1.57079 3.14159</pose>
          <geometry>
            <mesh>
              <scale>1 1 1</scale>
              <uri>/root/spibot_ws/src/sipder_robot/meshes/foot3.STL</uri>
            </mesh>
          </geometry>
          <surface>
            <contact>
              <ode/>
            </contact>
            <friction>
              <ode>
                <mu>1</mu>
                <mu2>1</mu2>
              </ode>
              <torsional>
                <ode/>
              </torsional>
            </friction>
            <bounce/>
          </surface>
          <max_contacts>10</max_contacts>
        </collision>
        <visual name='shank3_visual'>
          <pose>0 0 0 0 -0 0</pose>
          <geometry>
            <mesh>
              <scale>1 1 1</scale>
              <uri>/root/spibot_ws/src/sipder_robot/meshes/shank3.STL</uri>
            </mesh>
          </geometry>
          <material>
            <script>
              <name>Gazebo/Turquoise</name>
              <uri>file://media/materials/scripts/gazebo.material</uri>
            </script>
          </material>
        </visual>
        <visual name='shank3_fixed_joint_lump__foot3_visual_1'>
          <pose>0.36572 0 0.00075 3.14159 1.57079 3.14159</pose>
          <geometry>
            <mesh>
              <scale>1 1 1</scale>
              <uri>/root/spibot_ws/src/sipder_robot/meshes/foot3.STL</uri>
            </mesh>
          </geometry>
          <material>
            <script>
              <name>Gazebo/SkyBlue</name>
              <uri>file://media/materials/scripts/gazebo.material</uri>
            </script>
          </material>
        </visual>
        <self_collide>1</self_collide>
        <self_collide>1</self_collide>
        <enable_wind>0</enable_wind>
        <kinematic>0</kinematic>
      </link>
      <joint name='gripper3_joint' type='revolute'>
        <pose relative_to='shank3'>0.41772 0 0.00075 3.14159 1.57079 3.14159</pose>
        <parent>shank3</parent>
        <child>vacuum_gripper3</child>
        <axis>
          <xyz>1 0 0</xyz>
          <limit>
            <lower>0</lower>
            <upper>0</upper>
            <effort>50</effort>
            <velocity>50</velocity>
          </limit>
          <dynamics>
            <damping>0</damping>
            <friction>10</friction>
            <spring_reference>0</spring_reference>
            <spring_stiffness>0</spring_stiffness>
          </dynamics>
        </axis>
      </joint>
      <link name='vacuum_gripper3'>
        <pose relative_to='gripper3_joint'>0 0 0 0 -0 0</pose>
        <inertial>
          <pose>0 0 0 0 -0 0</pose>
          <mass>0.0001</mass>
          <inertia>
            <ixx>1e-08</ixx>
            <ixy>0</ixy>
            <ixz>0</ixz>
            <iyy>1e-08</iyy>
            <iyz>0</iyz>
            <izz>1e-08</izz>
          </inertia>
        </inertial>
        <visual name='vacuum_gripper3_visual'>
          <pose>0 0 0 0 -0 0</pose>
          <geometry>
            <cylinder>
              <length>0.01</length>
              <radius>0.05</radius>
            </cylinder>
          </geometry>
          <material>
            <script>
              <name>Gazebo/Grey</name>
              <uri>file://media/materials/scripts/gazebo.material</uri>
            </script>
          </material>
        </visual>
        <self_collide>0</self_collide>
        <enable_wind>0</enable_wind>
        <kinematic>0</kinematic>
      </link>
      <joint name='base2hip4' type='revolute'>
        <pose relative_to='dummy'>-0.11 -0.11 0.112 0 -0 3.14159</pose>
        <parent>dummy</parent>
        <child>hip4</child>
        <axis>
          <xyz>0 0 -1</xyz>
          <limit>
            <lower>-1.57</lower>
            <upper>1.57</upper>
            <effort>500</effort>
            <velocity>40</velocity>
          </limit>
          <dynamics>
            <spring_reference>0</spring_reference>
            <spring_stiffness>0</spring_stiffness>
          </dynamics>
        </axis>
      </joint>
      <link name='hip4'>
        <pose relative_to='base2hip4'>0 0 0 0 -0 0</pose>
        <inertial>
          <pose>0.02754 -0.03479 0.01969 0 -0 0</pose>
          <mass>0.03045</mass>
          <inertia>
            <ixx>1.02808e-05</ixx>
            <ixy>9.45871e-07</ixy>
            <ixz>-3.66419e-06</ixz>
            <iyy>2.45864e-05</iyy>
            <iyz>7.65591e-07</iyz>
            <izz>2.32546e-05</izz>
          </inertia>
        </inertial>
        <collision name='hip4_collision'>
          <pose>0 0 0 0 -0 0</pose>
          <geometry>
            <mesh>
              <scale>1 1 1</scale>
              <uri>/root/spibot_ws/src/sipder_robot/meshes/hip4.STL</uri>
            </mesh>
          </geometry>
          <surface>
            <contact>
              <ode/>
            </contact>
            <friction>
              <ode>
                <mu>0.3</mu>
                <mu2>0.3</mu2>
              </ode>
              <torsional>
                <ode/>
              </torsional>
            </friction>
            <bounce/>
          </surface>
          <max_contacts>10</max_contacts>
        </collision>
        <visual name='hip4_visual'>
          <pose>0 0 0 0 -0 0</pose>
          <geometry>
            <mesh>
              <scale>1 1 1</scale>
              <uri>/root/spibot_ws/src/sipder_robot/meshes/hip4.STL</uri>
            </mesh>
          </geometry>
          <material>
            <script>
              <name>Gazebo/RedBright</name>
              <uri>file://media/materials/scripts/gazebo.material</uri>
            </script>
          </material>
        </visual>
        <self_collide>0</self_collide>
        <enable_wind>0</enable_wind>
        <kinematic>0</kinematic>
      </link>
      <joint name='hip2thigh4' type='revolute'>
        <pose relative_to='hip4'>0.07 -0.0015 0.03 -1.5708 0 0</pose>
        <parent>hip4</parent>
        <child>thigh4</child>
        <axis>
          <xyz>0 0 -1</xyz>
          <limit>
            <lower>-3.14</lower>
            <upper>3.14</upper>
            <effort>500</effort>
            <velocity>40</velocity>
          </limit>
          <dynamics>
            <spring_reference>0</spring_reference>
            <spring_stiffness>0</spring_stiffness>
          </dynamics>
        </axis>
      </joint>
      <link name='thigh4'>
        <pose relative_to='hip2thigh4'>0 0 0 0 -0 0</pose>
        <inertial>
          <pose>0.11511 -9.5e-05 -0.005688 0 -0 0</pose>
          <mass>0.60857</mass>
          <inertia>
            <ixx>0.0002871</ixx>
            <ixy>-1.1416e-07</ixy>
            <ixz>4.4479e-08</ixz>
            <iyy>0.0013103</iyy>
            <iyz>-8.1337e-08</iyz>
            <izz>0.0015428</izz>
          </inertia>
        </inertial>
        <collision name='thigh4_collision'>
          <pose>0 0 0 0 -0 0</pose>
          <geometry>
            <mesh>
              <scale>1 1 1</scale>
              <uri>/root/spibot_ws/src/sipder_robot/meshes/thigh4.STL</uri>
            </mesh>
          </geometry>
          <surface>
            <contact>
              <ode/>
            </contact>
            <friction>
              <ode>
                <mu>0.3</mu>
                <mu2>0.3</mu2>
              </ode>
              <torsional>
                <ode/>
              </torsional>
            </friction>
            <bounce/>
          </surface>
          <max_contacts>10</max_contacts>
        </collision>
        <visual name='thigh4_visual'>
          <pose>0 0 0 0 -0 0</pose>
          <geometry>
            <mesh>
              <scale>1 1 1</scale>
              <uri>/root/spibot_ws/src/sipder_robot/meshes/thigh4.STL</uri>
            </mesh>
          </geometry>
          <material>
            <script>
              <name>Gazebo/Green</name>
              <uri>file://media/materials/scripts/gazebo.material</uri>
            </script>
          </material>
        </visual>
        <self_collide>1</self_collide>
        <enable_wind>0</enable_wind>
        <kinematic>0</kinematic>
      </link>
      <joint name='thigh2shank4' type='revolute'>
        <pose relative_to='thigh4'>0.23 0 0 0 -0 1.5708</pose>
        <parent>thigh4</parent>
        <child>shank4</child>
        <axis>
          <xyz>0 0 -1</xyz>
          <limit>
            <lower>-3.14</lower>
            <upper>3.14</upper>
            <effort>500</effort>
            <velocity>40</velocity>
          </limit>
          <dynamics>
            <spring_reference>0</spring_reference>
            <spring_stiffness>0</spring_stiffness>
          </dynamics>
        </axis>
      </joint>
      <link name='shank4'>
        <pose relative_to='thigh2shank4'>0 0 0 0 -0 0</pose>
        <inertial>
          <pose>0.2884 -4e-06 -0.002998 0 -0 0</pose>
          <mass>0.236895</mass>
          <inertia>
            <ixx>0.000187746</ixx>
            <ixy>7.54043e-08</ixy>
            <ixz>-0.000139702</ixz>
            <iyy>0.00351776</iyy>
            <iyz>5.23046e-09</iyz>
            <izz>0.00351833</izz>
          </inertia>
        </inertial>
        <collision name='shank4_collision'>
          <pose>0 0 0 0 -0 0</pose>
          <geometry>
            <mesh>
              <scale>1 1 1</scale>
              <uri>/root/spibot_ws/src/sipder_robot/meshes/shank4.STL</uri>
            </mesh>
          </geometry>
          <surface>
            <contact>
              <ode/>
            </contact>
            <friction>
              <ode>
                <mu>0.3</mu>
                <mu2>0.3</mu2>
              </ode>
              <torsional>
                <ode/>
              </torsional>
            </friction>
            <bounce/>
          </surface>
          <max_contacts>10</max_contacts>
        </collision>
        <collision name='shank4_fixed_joint_lump__foot4_collision_collision_1'>
          <pose>0.36572 0 0.00075 3.14159 1.57079 3.14159</pose>
          <geometry>
            <mesh>
              <scale>1 1 1</scale>
              <uri>/root/spibot_ws/src/sipder_robot/meshes/foot4.STL</uri>
            </mesh>
          </geometry>
          <surface>
            <contact>
              <ode/>
            </contact>
            <friction>
              <ode>
                <mu>1</mu>
                <mu2>1</mu2>
              </ode>
              <torsional>
                <ode/>
              </torsional>
            </friction>
            <bounce/>
          </surface>
          <max_contacts>10</max_contacts>
        </collision>
        <visual name='shank4_visual'>
          <pose>0 0 0 0 -0 0</pose>
          <geometry>
            <mesh>
              <scale>1 1 1</scale>
              <uri>/root/spibot_ws/src/sipder_robot/meshes/shank4.STL</uri>
            </mesh>
          </geometry>
          <material>
            <script>
              <name>Gazebo/Turquoise</name>
              <uri>file://media/materials/scripts/gazebo.material</uri>
            </script>
          </material>
        </visual>
        <visual name='shank4_fixed_joint_lump__foot4_visual_1'>
          <pose>0.36572 0 0.00075 3.14159 1.57079 3.14159</pose>
          <geometry>
            <mesh>
              <scale>1 1 1</scale>
              <uri>/root/spibot_ws/src/sipder_robot/meshes/foot4.STL</uri>
            </mesh>
          </geometry>
          <material>
            <script>
              <name>Gazebo/SkyBlue</name>
              <uri>file://media/materials/scripts/gazebo.material</uri>
            </script>
          </material>
        </visual>
        <self_collide>1</self_collide>
        <self_collide>1</self_collide>
        <enable_wind>0</enable_wind>
        <kinematic>0</kinematic>
      </link>
      <joint name='gripper4_joint' type='revolute'>
        <pose relative_to='shank4'>0.41772 0 0.00075 3.14159 1.57079 3.14159</pose>
        <parent>shank4</parent>
        <child>vacuum_gripper4</child>
        <axis>
          <xyz>1 0 0</xyz>
          <limit>
            <lower>0</lower>
            <upper>0</upper>
            <effort>50</effort>
            <velocity>50</velocity>
          </limit>
          <dynamics>
            <damping>0</damping>
            <friction>10</friction>
            <spring_reference>0</spring_reference>
            <spring_stiffness>0</spring_stiffness>
          </dynamics>
        </axis>
      </joint>
      <link name='vacuum_gripper4'>
        <pose relative_to='gripper4_joint'>0 0 0 0 -0 0</pose>
        <inertial>
          <pose>0 0 0 0 -0 0</pose>
          <mass>0.0001</mass>
          <inertia>
            <ixx>1e-08</ixx>
            <ixy>0</ixy>
            <ixz>0</ixz>
            <iyy>1e-08</iyy>
            <iyz>0</iyz>
            <izz>1e-08</izz>
          </inertia>
        </inertial>
        <visual name='vacuum_gripper4_visual'>
          <pose>0 0 0 0 -0 0</pose>
          <geometry>
            <cylinder>
              <length>0.01</length>
              <radius>0.05</radius>
            </cylinder>
          </geometry>
          <material>
            <script>
              <name>Gazebo/Grey</name>
              <uri>file://media/materials/scripts/gazebo.material</uri>
            </script>
          </material>
        </visual>
        <self_collide>0</self_collide>
        <enable_wind>0</enable_wind>
        <kinematic>0</kinematic>
      </link>
      <plugin name='gazebo_ros_control' filename='libgazebo_ros_control.so'>
        <robotNamespace>/spibot_gazebo</robotNamespace>
        <robotSimType>gazebo_ros_control/DefaultRobotHWSim</robotSimType>
      </plugin>
      <plugin name='p3d_base_controller' filename='libgazebo_ros_p3d.so'>
        <alwaysOn>1</alwaysOn>
        <updateRate>50.0</updateRate>
        <topicName>/odometry</topicName>
        <gaussianNoise>0.01</gaussianNoise>
        <frameName>map</frameName>
        <xyzOffsets>0 0 0</xyzOffsets>
        <rpyOffsets>0 0 0</rpyOffsets>
        <robotNamespace>/</robotNamespace>
        <bodyName>dummy</bodyName>
        <xyzOffset>0 0 0</xyzOffset>
        <rpyOffset>0 -0 0</rpyOffset>
        <ignition::corrected_offsets>1</ignition::corrected_offsets>
      </plugin>
      <plugin name='gazebo_ros_vacuum_gripper' filename='libgazebo_ros_vacuum_gripper.so'>
        <robotNamespace>/spibot_vacuum_gripper1</robotNamespace>
        <bodyName>vacuum_gripper1</bodyName>
        <topicName>BR_suction_state</topicName>
        <maxForce>400</maxForce>
        <maxDistance>0.05</maxDistance>
        <minDistance>0.01</minDistance>
      </plugin>
      <plugin name='gazebo_ros_vacuum_gripper' filename='libgazebo_ros_vacuum_gripper.so'>
        <robotNamespace>/spibot_vacuum_gripper2</robotNamespace>
        <bodyName>vacuum_gripper2</bodyName>
        <topicName>FR_suction_state</topicName>
        <maxForce>400</maxForce>
        <maxDistance>0.05</maxDistance>
        <minDistance>0.01</minDistance>
      </plugin>
      <plugin name='gazebo_ros_vacuum_gripper' filename='libgazebo_ros_vacuum_gripper.so'>
        <robotNamespace>/spibot_vacuum_gripper3</robotNamespace>
        <bodyName>vacuum_gripper3</bodyName>
        <topicName>FL_suction_state</topicName>
        <maxForce>400</maxForce>
        <maxDistance>0.05</maxDistance>
        <minDistance>0.01</minDistance>
      </plugin>
      <plugin name='gazebo_ros_vacuum_gripper' filename='libgazebo_ros_vacuum_gripper.so'>
        <robotNamespace>/spibot_vacuum_gripper4</robotNamespace>
        <bodyName>vacuum_gripper4</bodyName>
        <topicName>BL_suction_state</topicName>
        <maxForce>400</maxForce>
        <maxDistance>0.05</maxDistance>
        <minDistance>0.01</minDistance>
      </plugin>
      <frame name='base2camera' attached_to='base_link'>
        <pose>0.000633 0.17702 0.084 0 -0 1.57</pose>
      </frame>
      <frame name='camera' attached_to='base2camera'/>
      <frame name='base2lidar' attached_to='base_link'>
        <pose>8.7e-05 0.038511 -0.000556 3.14159 -0 -3.14159</pose>
      </frame>
      <frame name='lidar' attached_to='base2lidar'/>
      <frame name='dummy_joint' attached_to='dummy'>
        <pose>0 0 0 0 -0 0</pose>
      </frame>
      <frame name='base_link' attached_to='dummy_joint'/>
      <frame name='shank2foot1' attached_to='shank1'>
        <pose>0.36572 0 0.00075 1.55979 -1.57079 1.58179</pose>
      </frame>
      <frame name='foot1' attached_to='shank2foot1'/>
      <frame name='shank2foot2' attached_to='shank2'>
        <pose>0.36572 0 0.00075 1.56979 -1.57079 1.57179</pose>
      </frame>
      <frame name='foot2' attached_to='shank2foot2'/>
      <frame name='shank2foot3' attached_to='shank3'>
        <pose>0.36572 0 0.00075 3.14159 1.57079 3.14159</pose>
      </frame>
      <frame name='foot3' attached_to='shank2foot3'/>
      <frame name='shank2foot4' attached_to='shank4'>
        <pose>0.36572 0 0.00075 3.14159 1.57079 3.14159</pose>
      </frame>
      <frame name='foot4' attached_to='shank2foot4'/>
      <pose>0 0 0.3 0 -0 0</pose>
    </model>
    <model name='traj_base'>
      <joint name='world_joint' type='fixed'>
        <pose relative_to='__model__'>0 0 0 0 -0 0</pose>
        <parent>world</parent>
        <child>root</child>
      </joint>
      <link name='root'>
        <pose relative_to='world_joint'>0 0 0 0 -0 0</pose>
        <inertial>
          <pose>0 0 0 0 -0 0</pose>
          <mass>1e-05</mass>
          <inertia>
            <ixx>1e-06</ixx>
            <ixy>0</ixy>
            <ixz>0</ixz>
            <iyy>1e-06</iyy>
            <iyz>0</iyz>
            <izz>1e-06</izz>
          </inertia>
        </inertial>
        <visual name='root_visual'>
          <pose>0 0 0 0 -0 0</pose>
          <geometry>
            <box>
              <size>0.06 0.06 0.05</size>
            </box>
          </geometry>
          <plugin name='drawtrajPlugin' filename='libdraw_traj.so'>
            <topicName>/odometry</topicName>
            <robotNamespace>/</robotNamespace>
          </plugin>
        </visual>
        <self_collide>0</self_collide>
        <enable_wind>0</enable_wind>
        <kinematic>0</kinematic>
      </link>
      <pose>0 0 0 0 -0 0</pose>
    </model>
    <model name='unit_box_2'>
      <pose>0.914303 1.53633 0.5 0 -0 0</pose>
      <link name='link'>
        <inertial>
          <mass>1</mass>
          <inertia>
            <ixx>0.166667</ixx>
            <ixy>0</ixy>
            <ixz>0</ixz>
            <iyy>0.166667</iyy>
            <iyz>0</iyz>
            <izz>0.166667</izz>
          </inertia>
          <pose>0 0 0 0 -0 0</pose>
        </inertial>
        <collision name='collision'>
          <geometry>
            <box>
              <size>0.999997 0.999998 0.999989</size>
            </box>
          </geometry>
          <max_contacts>10</max_contacts>
          <surface>
            <contact>
              <ode/>
            </contact>
            <bounce/>
            <friction>
              <torsional>
                <ode/>
              </torsional>
              <ode/>
            </friction>
          </surface>
        </collision>
        <visual name='visual'>
          <geometry>
            <box>
              <size>0.999997 0.999998 0.999989</size>
            </box>
          </geometry>
          <material>
            <script>
              <name>Gazebo/Red</name>
              <uri>file://media/materials/scripts/gazebo.material</uri>
            </script>
          </material>
        </visual>
        <self_collide>0</self_collide>
        <enable_wind>0</enable_wind>
        <kinematic>0</kinematic>
      </link>
    </model>
  </world>
</sdf>
