<?xml version="1.0" encoding="utf-8"?>
<!-- This URDF was automatically created by SolidWorks to URDF Exporter! Originally created by Stephen Brawner (brawner@gmail.com) 
     Commit Version: 1.6.0-4-g7f85cfe  Build Version: 1.6.7995.38578
     For more information, please see http://wiki.ros.org/sw_urdf_exporter -->
<robot name="sipder_robot">
  <link name="dummy">
    <visual>
      <origin rpy="0 0 0" xyz="0 0 0"/>
      <geometry>
        <box size="0.001 0.001 0.001"/>
      </geometry>
    </visual>
  </link>

  <joint name="dummy_joint" type="fixed">
    <origin rpy="0 0 0" xyz="0 0 0"/>
    <parent link="dummy"/>
    <child link="base_link"/>
  </joint>

  <link name="base_link">
    <inertial>
      <origin xyz="9.5983E-05 -0.0053069 0.074681" rpy="0 0 0" />
      <mass value="2.8003" />
      <inertia ixx="0.0051964" ixy="1.4763E-06" ixz="-1.4439E-06" iyy="0.0055771" iyz="2.0006E-07" izz="0.010212" />
    </inertial>
    <visual>
      <origin xyz="0 0 0" rpy="0 0 0" />
      <geometry>
        <mesh filename="package://sipder_robot/meshes/spibot/base_link.STL" />
      </geometry>
      <material name="">
        <color rgba="0 0 0 1" />
      </material>
    </visual>
    <collision>
      <origin xyz="0 0 0" rpy="0 0 0" />
      <geometry>
        <mesh filename="package://sipder_robot/meshes/spibot/base_link.STL" />
      </geometry>
    </collision>
  </link>

  <link name="hip1">
    <inertial>
      <origin xyz="0.030542 -0.027829 0.01669" rpy="0 0 0" />
      <mass value="0.030452" />
      <inertia ixx="1.0281E-05" ixy="9.4587E-07" ixz="-3.6642E-06" iyy="2.4586E-05" iyz="7.6559E-07" izz="2.3255E-05" />
    </inertial>
    <visual>
      <origin xyz="0 0 0" rpy="0 0 0" />
      <geometry>
        <mesh filename="package://sipder_robot/meshes/spibot/hip1.STL" />
      </geometry>
      <material name="">
        <color rgba="1 1 1 1" />
      </material>
    </visual>
    <collision>
      <origin xyz="0 0 0" rpy="0 0 0" />
      <geometry>
        <mesh filename="package://sipder_robot/meshes/spibot/hip1.STL" />
      </geometry>
    </collision>
  </link>
  <joint name="base2hip1" type="revolute">
    <origin xyz="0.11 -0.11 0.112" rpy="0 0 -0.7854" />
    <parent link="base_link" />
    <child link="hip1" />
    <axis xyz="0 0 1" />
    <limit lower="-1.57" upper="1.57" effort="500" velocity="40" />
    <dynamics damping="0.0" friction="0.0"/>
  </joint>
  <link name="thigh1">
    <inertial>
      <origin xyz="0.11489 9.5371E-05 -0.0056875" rpy="0 0 0" />
      <mass value="0.60857" />
      <inertia ixx="0.0002871" ixy="-1.1416E-07" ixz="-4.4479E-08" iyy="0.0013103" iyz="8.1337E-08" izz="0.0015428" />
    </inertial>
    <visual>
      <origin xyz="0 0 0" rpy="0 0 0" />
      <geometry>
        <mesh filename="package://sipder_robot/meshes/spibot/thigh1.STL" />
      </geometry>
      <material name="">
        <color rgba="0 0 1 1" />
      </material>
    </visual>
    <collision>
      <origin xyz="0 0 0" rpy="0 0 0" />
      <geometry>
        <mesh filename="package://sipder_robot/meshes/spibot/thigh1.STL" />
      </geometry>
    </collision>
  </link>
  <joint name="hip2thigh1" type="revolute">
    <origin xyz="0.07 -0.0015 0.03" rpy="-1.5708 -0.53703 0" />
    <parent link="hip1" />
    <child link="thigh1" />
    <axis xyz="0 0 1" />
    <limit lower="-3.14" upper="3.14" effort="500" velocity="40" />
  </joint>
  <link name="shank1">
    <inertial>
      <origin xyz="0.13117 2.9976E-15 -0.010092" rpy="0 0 0" />
      <mass value="0.081935" />
      <inertia ixx="1.8823E-05" ixy="1.1047E-19" ixz="1.433E-19" iyy="0.00031144" iyz="-2.3039E-19" izz="0.00031833" />
    </inertial>
    <visual>
      <origin xyz="0 0 0" rpy="0 0 0" />
      <geometry>
        <mesh filename="package://sipder_robot/meshes/spibot/shank1.STL" />
      </geometry>
      <material name="">
        <color rgba="1 1 0 1" />
      </material>
    </visual>
    <collision>
      <origin xyz="0 0 0" rpy="0 0 0" />
      <geometry>
        <mesh filename="package://sipder_robot/meshes/spibot/shank1.STL" />
      </geometry>
    </collision>
  </link>
  <joint name="thigh2shank1" type="revolute">
    <origin xyz="0.23 0 0" rpy="0 0 2.1078" />
    <parent link="thigh1" />
    <child link="shank1" />
    <axis xyz="0 0 1" />
    <limit lower="-3.14" upper="3.14" effort="500" velocity="40" />
  </joint>
  <link name="foot1">
    <inertial>
      <origin xyz="-5.0263E-06 -3.7565E-06 0.0058146" rpy="0 0 0" />
      <mass value="0.15496" />
      <inertia ixx="0.00010348" ixy="4.8068E-09" ixz="-6.6695E-10" iyy="0.00010349" iyz="8.8051E-10" izz="0.00016262" />
    </inertial>
    <visual>
      <origin xyz="0 0 0" rpy="0 0 0" />
      <geometry>
        <mesh filename="package://sipder_robot/meshes/spibot/foot1.STL" />
      </geometry>
      <material name="">
        <color rgba="0 1 1 1" />
      </material>
    </visual>
    <collision>
      <origin xyz="0 0 0" rpy="0 0 0" />
      <geometry>
        <mesh filename="package://sipder_robot/meshes/spibot/foot1.STL" />
      </geometry>
    </collision>
  </link>
  <joint name="shank2foot1" type="revolute">
    <origin xyz="0.36572 0 0.00075" rpy="-1.5818 -1.5708 -1.5598" />
    <parent link="shank1" />
    <child link="foot1" />
    <axis xyz="0 0 -1" />
  </joint>
  <link name="hip2">
    <inertial>
      <origin xyz="0.0019183 -0.041274 0.01669" rpy="0 0 0" />
      <mass value="0.030452" />
      <inertia ixx="1.8379E-05" ixy="7.1528E-06" ixz="-2.0496E-06" iyy="1.6488E-05" iyz="3.1323E-06" izz="2.3255E-05" />
    </inertial>
    <visual>
      <origin xyz="0 0 0" rpy="0 0 0" />
      <geometry>
        <mesh filename="package://sipder_robot/meshes/spibot/hip2.STL" />
      </geometry>
      <material name="">
        <color rgba="1 1 1 1" />
      </material>
    </visual>
    <collision>
      <origin xyz="0 0 0" rpy="0 0 0" />
      <geometry>
        <mesh filename="package://sipder_robot/meshes/spibot/hip2.STL" />
      </geometry>
    </collision>
  </link>
  <joint name="base2hip2" type="revolute">
    <origin xyz="0.11 0.11 0.112" rpy="0 0 1.5708" />
    <parent link="base_link" />
    <child link="hip2" />
    <axis xyz="0 0 -1" />
    <limit lower="-1.57" upper="1.57" effort="500" velocity="40" />
  </joint>
  <link name="thigh2">
    <inertial>
      <origin xyz="0.11489 9.5371E-05 -0.0056875" rpy="0 0 0" />
      <mass value="0.60857" />
      <inertia ixx="0.0002871" ixy="-1.1416E-07" ixz="-4.4479E-08" iyy="0.0013103" iyz="8.1337E-08" izz="0.0015428" />
    </inertial>
    <visual>
      <origin xyz="0 0 0" rpy="0 0 0" />
      <geometry>
        <mesh filename="package://sipder_robot/meshes/spibot/thigh2.STL" />
      </geometry>
      <material name="">
        <color rgba="0 0 1 1" />
      </material>
    </visual>
    <collision>
      <origin xyz="0 0 0" rpy="0 0 0" />
      <geometry>
        <mesh filename="package://sipder_robot/meshes/spibot/thigh2.STL" />
      </geometry>
    </collision>
  </link>
  <joint name="hip2thigh2" type="revolute">
    <origin xyz="0.048437 -0.050558 0.03" rpy="-1.5708 -0.53703 -0.7854" />
    <parent link="hip2" />
    <child link="thigh2" />
    <axis xyz="0 0 -1" />
    <limit lower="-3.14" upper="3.14" effort="500" velocity="40" />
  </joint>
  <link name="shank2">
    <inertial>
      <origin xyz="0.13117 -1.1102E-16 -0.010092" rpy="0 0 0" />
      <mass value="0.081935" />
      <inertia ixx="1.8823E-05" ixy="1.1765E-19" ixz="1.4556E-19" iyy="0.00031144" iyz="-2.3039E-19" izz="0.00031833" />
    </inertial>
    <visual>
      <origin xyz="0 0 0" rpy="0 0 0" />
      <geometry>
        <mesh filename="package://sipder_robot/meshes/spibot/shank2.STL" />
      </geometry>
      <material name="">
        <color rgba="1 1 0 1" />
      </material>
    </visual>
    <collision>
      <origin xyz="0 0 0" rpy="0 0 0" />
      <geometry>
        <mesh filename="package://sipder_robot/meshes/spibot/shank2.STL" />
      </geometry>
    </collision>
  </link>
  <joint name="thigh2shank2" type="revolute">
    <origin xyz="0.23 0 0" rpy="0 0 2.1078" />
    <parent link="thigh2" />
    <child link="shank2" />
    <axis xyz="0 0 1" />
    <limit lower="-3.14" upper="3.14" effort="500" velocity="40" />
  </joint>
  <link name="foot2">
    <inertial>
      <origin xyz="-6.261E-06 -7.1023E-07 0.0058163" rpy="0 0 0" />
      <mass value="0.15495" />
      <inertia ixx="0.00010349" ixy="6.309E-09" ixz="-1.5247E-10" iyy="0.00010349" iyz="1.118E-09" izz="0.00016262" />
    </inertial>
    <visual>
      <origin xyz="0 0 0" rpy="0 0 0" />
      <geometry>
        <mesh filename="package://sipder_robot/meshes/spibot/foot2.STL" />
      </geometry>
      <material name="">
        <color rgba="0 1 1 1" />
      </material>
    </visual>
    <collision>
      <origin xyz="0 0 0" rpy="0 0 0" />
      <geometry>
        <mesh filename="package://sipder_robot/meshes/spibot/foot2.STL" />
      </geometry>
    </collision>
  </link>
  <joint name="shank2foot2" type="revolute">
    <origin xyz="0.36572 0 0.00075" rpy="-1.5718 -1.5708 -1.5698" />
    <parent link="shank2" />
    <child link="foot2" />
    <axis xyz="0 0 -1" />
  </joint>
  <link name="hip3">
    <inertial>
      <origin xyz="0.0305418203173762 -0.0278289406897 0.016689897603681" rpy="0 0 0" />
      <mass value="0.030451957754817" />
      <inertia ixx="1.02807543656808E-05" ixy="9.45871271693215E-07" ixz="-3.66419156962914E-06" iyy="2.45863839494372E-05" iyz="7.65590783313748E-07" izz="2.32546439357208E-05" />
    </inertial>
    <visual>
      <origin xyz="0 0 0" rpy="0 0 0" />
      <geometry>
        <mesh filename="package://sipder_robot/meshes/spibot/hip3.STL" />
      </geometry>
      <material name="">
        <color rgba="1 1 1 1" />
      </material>
    </visual>
    <collision>
      <origin xyz="0 0 0" rpy="0 0 0" />
      <geometry>
        <mesh filename="package://sipder_robot/meshes/spibot/hip3.STL" />
      </geometry>
    </collision>
  </link>
  <joint name="base2hip3" type="revolute">
    <origin xyz="-0.11 0.11 0.112" rpy="0 0 2.3562" />
    <parent link="base_link" />
    <child link="hip3" />
    <axis xyz="0 0 1" />
    <limit lower="-1.57" upper="1.57" effort="500" velocity="40" />
  </joint>
  <link name="thigh3">
    <inertial>
      <origin xyz="0.11489 9.5371E-05 -0.0056875" rpy="0 0 0" />
      <mass value="0.60857" />
      <inertia ixx="0.0002871" ixy="-1.1416E-07" ixz="-4.4479E-08" iyy="0.0013103" iyz="8.1337E-08" izz="0.0015428" />
    </inertial>
    <visual>
      <origin xyz="0 0 0" rpy="0 0 0" />
      <geometry>
        <mesh filename="package://sipder_robot/meshes/spibot/thigh3.STL" />
      </geometry>
      <material name="">
        <color rgba="0 0 1 1" />
      </material>
    </visual>
    <collision>
      <origin xyz="0 0 0" rpy="0 0 0" />
      <geometry>
        <mesh filename="package://sipder_robot/meshes/spibot/thigh3.STL" />
      </geometry>
    </collision>
  </link>
  <joint name="hip2thigh3" type="revolute">
    <origin xyz="0.07 -0.0015 0.03" rpy="-1.5708 -0.53703 0" />
    <parent link="hip3" />
    <child link="thigh3" />
    <axis xyz="0 0 -1" />
    <limit lower="-3.14" upper="3.14" effort="500" velocity="40" />
  </joint>
  <link name="shank3">
    <inertial>
      <origin xyz="0.13117 -4.7184E-15 -0.010092" rpy="0 0 0" />
      <mass value="0.081935" />
      <inertia ixx="1.8823E-05" ixy="1.4305E-19" ixz="8.5825E-20" iyy="0.00031144" iyz="-2.7105E-20" izz="0.00031833" />
    </inertial>
    <visual>
      <origin xyz="0 0 0" rpy="0 0 0" />
      <geometry>
        <mesh filename="package://sipder_robot/meshes/spibot/shank3.STL" />
      </geometry>
      <material name="">
        <color rgba="1 1 0 1" />
      </material>
    </visual>
    <collision>
      <origin xyz="0 0 0" rpy="0 0 0" />
      <geometry>
        <mesh filename="package://sipder_robot/meshes/spibot/shank3.STL" />
      </geometry>
    </collision>
  </link>
  <joint name="thigh2shank3" type="revolute">
    <origin xyz="0.23 0 0" rpy="0 0 2.1078" />
    <parent link="thigh3" />
    <child link="shank3" />
    <axis xyz="0 0 -1" />
    <limit lower="-3.14" upper="3.14" effort="500" velocity="40" />
  </joint>
  <link name="foot3">
    <inertial>
      <origin xyz="-2.0374E-06 -5.9535E-06 0.0058152" rpy="0 0 0" />
      <mass value="0.15496" />
      <inertia ixx="0.00010348" ixy="-2.4176E-09" ixz="-1.0478E-09" iyy="0.00010349" iyz="3.5161E-10" izz="0.00016262" />
    </inertial>
    <visual>
      <origin xyz="0 0 0" rpy="0 0 0" />
      <geometry>
        <mesh filename="package://sipder_robot/meshes/spibot/foot3.STL" />
      </geometry>
      <material name="">
        <color rgba="0 1 1 1" />
      </material>
    </visual>
    <collision>
      <origin xyz="0 0 0" rpy="0 0 0" />
      <geometry>
        <mesh filename="package://sipder_robot/meshes/spibot/foot3.STL" />
      </geometry>
    </collision>
  </link>
  <joint name="shank2foot3" type="fixed">
    <origin xyz="0.36572 0 0.00075" rpy="0 1.5708 0" />
    <parent link="shank3" />
    <child link="foot3" />
    <axis xyz="0 0 -1" />
  </joint>
  <link name="hip4">
    <inertial>
      <origin xyz="0.0305418203173761 -0.0278289406982714 0.0166898975893889" rpy="0 0 0" />
      <mass value="0.0304519577548169" />
      <inertia ixx="1.02807543656808E-05" ixy="9.45871273575032E-07" ixz="-3.66419156914335E-06" iyy="2.45863839486507E-05" iyz="7.65590783997688E-07" izz="2.3254643936507E-05" />
    </inertial>
    <visual>
      <origin xyz="0 0 0" rpy="0 0 0" />
      <geometry>
        <mesh filename="package://sipder_robot/meshes/spibot/hip4.STL" />
      </geometry>
      <material name="">
        <color rgba="1 1 1 1" />
      </material>
    </visual>
    <collision>
      <origin xyz="0 0 0" rpy="0 0 0" />
      <geometry>
        <mesh filename="package://sipder_robot/meshes/spibot/hip4.STL" />
      </geometry>
    </collision>
  </link>
  <joint name="base2hip4" type="revolute">
    <origin xyz="-0.11 -0.11 0.112" rpy="0 0 -2.3562" />
    <parent link="base_link" />
    <child link="hip4" />
    <axis xyz="0 0 -1" />
    <limit lower="-1.57" upper="1.57" effort="500" velocity="40" />
  </joint>
  <link name="thigh4">
    <inertial>
      <origin xyz="0.11511 -9.5371E-05 -0.0056875" rpy="0 0 0" />
      <mass value="0.60857" />
      <inertia ixx="0.0002871" ixy="-1.1416E-07" ixz="4.4479E-08" iyy="0.0013103" iyz="-8.1337E-08" izz="0.0015428" />
    </inertial>
    <visual>
      <origin xyz="0 0 0" rpy="0 0 0" />
      <geometry>
        <mesh filename="package://sipder_robot/meshes/spibot/thigh4.STL" />
      </geometry>
      <material name="">
        <color rgba="0 0 1 1" />
      </material>
    </visual>
    <collision>
      <origin xyz="0 0 0" rpy="0 0 0" />
      <geometry>
        <mesh filename="package://sipder_robot/meshes/spibot/thigh4.STL" />
      </geometry>
    </collision>
  </link>
  <joint name="hip2thigh4" type="revolute">
    <origin xyz="0.07 -0.0015 0.03" rpy="-1.5708 -0.53703 0" />
    <parent link="hip4" />
    <child link="thigh4" />
    <axis xyz="0 0 -1" />
    <limit lower="-3.14" upper="3.14" effort="500" velocity="40" />
  </joint>
  <link name="shank4">
    <inertial>
      <origin xyz="0.13117 6.3838E-15 -0.010092" rpy="0 0 0" />
      <mass value="0.081935" />
      <inertia ixx="1.8823E-05" ixy="-1.0405E-19" ixz="-1.52E-19" iyy="0.00031144" iyz="-8.1315E-20" izz="0.00031833" />
    </inertial>
    <visual>
      <origin xyz="0 0 0" rpy="0 0 0" />
      <geometry>
        <mesh filename="package://sipder_robot/meshes/spibot/shank4.STL" />
      </geometry>
      <material name="">
        <color rgba="1 1 0 1" />
      </material>
    </visual>
    <collision>
      <origin xyz="0 0 0" rpy="0 0 0" />
      <geometry>
        <mesh filename="package://sipder_robot/meshes/spibot/shank4.STL" />
      </geometry>
    </collision>
  </link>
  <joint name="thigh2shank4" type="revolute">
    <origin xyz="0.23 0 0" rpy="0 0 2.1078" />
    <parent link="thigh4" />
    <child link="shank4" />
    <axis xyz="0 0 -1" />
    <limit lower="-3.14" upper="3.14" effort="500" velocity="40" />
  </joint>
  <link name="foot4">
    <inertial>
      <origin xyz="-2.342E-06 -5.8217E-06 0.0058146" rpy="0 0 0" />
      <mass value="0.15496" />
      <inertia ixx="0.00010348" ixy="-1.8468E-09" ixz="-1.0274E-09" iyy="0.0001035" iyz="4.0565E-10" izz="0.00016262" />
    </inertial>
    <visual>
      <origin xyz="0 0 0" rpy="0 0 0" />
      <geometry>
        <mesh filename="package://sipder_robot/meshes/spibot/foot4.STL" />
      </geometry>
      <material name="">
        <color rgba="0 1 1 1" />
      </material>
    </visual>
    <collision>
      <origin xyz="0 0 0" rpy="0 0 0" />
      <geometry>
        <mesh filename="package://sipder_robot/meshes/spibot/foot4.STL" />
      </geometry>
    </collision>
  </link>
  <joint name="shank2foot4" type="revolute">
    <origin xyz="0.36572 0 0.00075" rpy="0 1.5708 0" />
    <parent link="shank4" />
    <child link="foot4" />
    <axis xyz="0 0 -1" />
  </joint>
  <link name="camera">
    <inertial>
      <origin xyz="0 0 0" rpy="0 0 0" />
      <mass value="0" />
      <inertia ixx="0" ixy="0" ixz="0" iyy="0" iyz="0" izz="0" />
    </inertial>
    <visual>
      <origin xyz="0 0 0" rpy="0 0 0" />
      <geometry>
        <mesh filename="package://sipder_robot/meshes/spibot/camera.STL" />
      </geometry>
      <material name="">
        <color rgba="1 1 1 1" />
      </material>
    </visual>
    <collision>
      <origin xyz="0 0 0" rpy="0 0 0" />
      <geometry>
        <mesh filename="package://sipder_robot/meshes/spibot/camera.STL" />
      </geometry>
    </collision>
  </link>
  <joint name="base2camera" type="fixed">
    <origin xyz="0.00063297 0.17702 0.084" rpy="-1.5708 0 3.1416" />
    <parent link="base_link" />
    <child link="camera" />
    <axis xyz="0 0 0" />
  </joint>
  <link name="lidar">
    <inertial>
      <origin xyz="-6.179E-05 -2.4592E-05 0.031978" rpy="0 0 0" />
      <mass value="0.1152" />
      <inertia ixx="3.8374E-05" ixy="-5.0651E-06" ixz="5.6483E-08" iyy="4.8506E-05" iyz="2.5161E-08" izz="6.975E-05" />
    </inertial>
    <visual>
      <origin xyz="0 0 0" rpy="0 0 0" />
      <geometry>
        <mesh filename="package://sipder_robot/meshes/spibot/lidar.STL" />
      </geometry>
      <material name="">
        <color rgba="0.79216 0.81961 0.93333 1" />
      </material>
    </visual>
    <collision>
      <origin xyz="0 0 0" rpy="0 0 0" />
      <geometry>
        <mesh filename="package://sipder_robot/meshes/spibot/lidar.STL" />
      </geometry>
    </collision>
  </link>
  <joint name="base2lidar" type="fixed">
    <origin xyz="8.7201E-05 0.038511 -0.000556" rpy="-3.1416 0 3.1416" />
    <parent link="base_link" />
    <child link="lidar" />
    <axis xyz="0 0 0" />
  </joint>
  <gazebo reference="base_link">
    <material>Gazebo/White</material>
  </gazebo>
  <gazebo reference="camera">
    <material>Gazebo/DarkGrey</material>
  </gazebo>
  <gazebo reference="lidar">
    <material>Gazebo/Indigo</material>
  </gazebo>
  <gazebo reference="hip1">
    <material>Gazebo/RedBright</material>
  </gazebo>
  <gazebo reference="hip2">
    <material>Gazebo/RedBright</material>
  </gazebo>
  <gazebo reference="hip3">
    <material>Gazebo/RedBright</material>
  </gazebo>
  <gazebo reference="hip4">
    <material>Gazebo/RedBright</material>
  </gazebo>
  <gazebo reference="thigh1">
    <material>Gazebo/Green</material>
  </gazebo>
  <gazebo reference="thigh2">
    <material>Gazebo/Green</material>
  </gazebo>
  <gazebo reference="thigh3">
    <material>Gazebo/Green</material>
  </gazebo>
  <gazebo reference="thigh4">
    <material>Gazebo/Green</material>
  </gazebo>
  <gazebo reference="shank1">
    <material>Gazebo/Turquoise</material>
  </gazebo>
  <gazebo reference="shank2">
    <material>Gazebo/Turquoise</material>
  </gazebo>
  <gazebo reference="shank3">
    <material>Gazebo/Turquoise</material>
  </gazebo>
  <gazebo reference="shank4">
    <material>Gazebo/Turquoise</material>
  </gazebo>
  <gazebo reference="foot1">
    <material>Gazebo/SkyBlue</material>
  </gazebo>
  <gazebo reference="foot2">
    <material>Gazebo/SkyBlue</material>
  </gazebo>
  <gazebo reference="foot3">
    <material>Gazebo/SkyBlue</material>    <!--反转,-1.57->1.57-->
  </gazebo>
  <gazebo reference="foot4">
    <material>Gazebo/SkyBlue</material>    <!--反转,-1.57->1.57-->
  </gazebo>
</robot>


