<?xml version="1.0" encoding="utf-8"?>
<!-- This URDF was automatically created by SolidWorks to URDF Exporter! Originally created by Stephen Brawner (brawner@gmail.com) 
     Commit Version: 1.6.0-4-g7f85cfe  Build Version: 1.6.7995.38578
     For more information, please see http://wiki.ros.org/sw_urdf_exporter -->
<robot name="SpibotRl">
  <link name="base">
    <inertial>
      <origin xyz="-0.0053069 -9.5983E-05 0.024681" rpy="0 0 0" />
      <mass value="8.956765" />
      <inertia ixx="0.109196" ixy="0.0" ixz="0.0" iyy="0.084796" iyz="0.0" izz="0.159461" />
    </inertial>
    <visual>
      <origin xyz="0 0 0" rpy="0 0 0" />
      <geometry>
        <box size="0.304 0.304 0.109" />
      </geometry>
      <material name="">
        <color rgba="1 1 1 1" />
      </material>
    </visual>
    <collision>
      <origin xyz="0 0 0" rpy="0 0 0" />
      <geometry>
        <box size="0.304 0.304 0.109" />
      </geometry>
    </collision>
  </link>
  <link name="RR_hip">
    <visual>
      <origin xyz="0 0 0" rpy="0 0 0" />
      <geometry>
        <sphere radius="0.031" />
      </geometry>
      <material name="">
        <color rgba="1 1 1 1" />
      </material>
    </visual>
    <collision>
      <origin xyz="0 0 0" rpy="0 0 0" />
      <geometry>
        <sphere radius="0.031" />
      </geometry>
    </collision>
  </link>
  <joint name="RR_hip_joint" type="revolute">
    <origin xyz="-0.11 -0.11 0.025" rpy="0 0 0" />
    <parent link="base" />
    <child link="RR_hip" />
    <axis xyz="0 0 1" />
    <limit lower="-0.25" upper="1.85" effort="100" velocity="30" />
  </joint>

  <link name="RR_thigh">
    <visual>
      <origin xyz="0 0 0" rpy="0 0 0" />
      <geometry>
        <sphere radius="0.031" />
      </geometry>
      <material name="">
        <color rgba="1 1 1 1" />
      </material>
    </visual>
    <collision>
      <origin xyz="0 0 0" rpy="0 0 0" />
      <geometry>
        <sphere radius="0.031" />
      </geometry>
    </collision>
  </link>
  <joint name="RR_thigh_joint" type="revolute">
    <origin xyz="-0.07 0.0015 0.067" rpy="0 0 0" />
    <parent link="RR_hip" />
    <child link="RR_thigh" />
    <axis xyz="0 -1 0" />
    <limit lower="-2.0" upper="1.0" effort="100" velocity="30" />
  </joint>

  <link name="RR_calf">
    <visual>
      <origin xyz="0 0 0" rpy="0 0 0" />
      <geometry>
        <sphere radius="0.031" />
      </geometry>
      <material name="">
        <color rgba="1 1 1 1" />
      </material>
    </visual>
    <collision>
      <origin xyz="0 0 0" rpy="0 0 0" />
      <geometry>
        <sphere radius="0.031" />
      </geometry>
    </collision>
  </link>
  <joint name="RR_calf_joint" type="revolute">
    <origin xyz="-0.23 0 0" rpy="3.1416 -1.5708 0" />
    <parent link="RR_thigh" />
    <child link="RR_calf" />
    <axis xyz="0 -1 0" />
    <limit lower="-0.55" upper="2.0" effort="100" velocity="30" />
  </joint>

  <link name="RR_foot">
    <visual>
      <origin xyz="0 0 0" rpy="0 0 0" />
      <geometry>
        <sphere radius="0.054" />
      </geometry>
      <material name="">
        <color rgba="1 1 1 1" />
      </material>
    </visual>
    <collision>
      <origin xyz="0 0 0" rpy="0 0 0" />
      <geometry>
        <sphere radius="0.054" />
      </geometry>
    </collision>
  </link>
  <joint name="RR_foot_joint" type="fixed" dont_collapse="true">
    <origin xyz="-0.36572 -0.00075 0" rpy="0 0 0" />
    <parent link="RR_calf" />
    <child link="RR_foot" />
    <axis xyz="0 0 0" />
  </joint>

</robot>